Workbook

Sheet Players
A1: Player | B1: Team 26/27 | C1: Pos | D1: Pos 25/26 | E1: Price 26/27 | F1: Draftable | G1: Played 25/26 | H1: Age | I1: Status | J1: News | K1: Chance next GW % | L1: Opta ID | M1: FPL ID | N1: Pens order | O1: Corners/IFK order | P1: Direct FK order | Q1: Mins | R1: Apps | S1: Starts | T1: 90s | U1: Mins per app | V1: FPL points | W1: FPL pts/90 | X1: Goals | Y1: Assists (FPL) | Z1: Assists (Opta) | AA1: Clean sheets | AB1: Goals conceded | AC1: Bonus | AD1: Bonus (new rules) | AE1: Bonus change | AF1: BPS | AG1: BPS (new rules) | AH1: BPS change | AI1: Points (new rules) | AJ1: Bonus per point | AK1: Bonus per non-bonus point | AL1: DefCon actions | AM1: DefCon actions/90 | AN1: DefCon matches | AO1: DefCon points | AP1: DefCon hit rate | AQ1: DefCon rate at 10 | AR1: DefCon rate at 12 | AS1: Start rate | AT1: 60+ min rate | AU1: Blanks | AV1: Hauls | AW1: Points SD | AX1: Best GW | AY1: xG (Opta) | AZ1: xG (Understat) | BA1: xG (blend) | BB1: npxG (Understat) | BC1: xG/90 (Opta) | BD1: xG/90 (Understat) | BE1: xG/90 (blend) | BF1: xGOT | BG1: xGOT/90 | BH1: Placement ratio | BI1: Placement sample xG | BJ1: Adjusted xGOT | BK1: Adjusted xGOT/90 | BL1: Goals - xG | BM1: xGOT - xG | BN1: Goals - xGOT | BO1: xG model gap | BP1: Shots | BQ1: Shots on target | BR1: Big chances missed | BS1: Touches in box | BT1: Touches in box/90 | BU1: Pen goals | BV1: Headed goals | BW1: xA (Opta) | BX1: xA (Understat) | BY1: xA (blend) | BZ1: xA/90 (blend) | CA1: xGI (blend) | CB1: xGI/90 (blend) | CC1: Key passes | CD1: Big chances created | CE1: Chances created | CF1: Crosses (acc) | CG1: Through balls (acc) | CH1: Corners taken | CI1: xGChain | CJ1: xGBuildup | CK1: CBI | CL1: Recoveries | CM1: Tackles | CN1: Tackles won | CO1: Interceptions | CP1: Clearances | CQ1: Blocks | CR1: Duels won | CS1: Aerials won | CT1: Poss won att 3rd/90 | CU1: Errors -> goal | CV1: Errors -> shot | CW1: xGC (Opta) | CX1: xGC/90 | CY1: Saves | CZ1: Save % | DA1: Goals prevented | DB1: Pens saved | DC1: High claims | DD1: Punches | DE1: FotMob rating | DF1: Yellows | DG1: Reds | DH1: Fouls | DI1: Fouled | DJ1: Pens won | DK1: Pens conceded | DL1: Dribbles won | DM1: Dispossessed | DN1: Offsides | DO1: Selected by % | DP1: Solio season pts | DQ1: Solio H1 pts (GW1-19) | DR1: Solio naive x2 | DS1: Solio correction | DT1: Solio xMins (season) | DU1: Solio xMins (settled) | DV1: Solio xMins pattern | DW1: ADP | DX1: ADP (8-team only) | DY1: ADP (last 7 days) | DZ1: ADP move | EA1: Times drafted (recent) | EB1: ADP spread | EC1: ADP earliest | ED1: ADP latest | EE1: Times drafted | EF1: ADP reliable | EG1: Drafted % | EH1: Auto-pick % | EI1: FPL draft rank | EJ1: Mins per shot | EK1: Mins per touch in box | EL1: Mins per chance created | EM1: Mins per xG (blend) | EN1: Mins per xA (blend) | EO1: Mins per xGI (blend) | EP1: Mins per point
A2: Erling Haaland | B2: MCI | C2: FWD | D2: FWD | E2: 15.5 | F2: TRUE | G2: TRUE | H2: 26.1 | I2: a | L2: p223094 | M2: 411 | N2: 1 | Q2: 2953 | R2: 35 | S2: 34 | T2: 32.811 | U2: 84.4 | V2: 239 | W2: 7.284 | X2: 27 | Y2: 8 | Z2: 8 | AA2: 13 | AB2: 32 | AC2: 43 | AD2: 43 | AE2: 0 | AF2: 952 | AG2: 943 | AH2: -9 | AI2: 239 | AJ2: 0.18 | AK2: 0.219 | AL2: 104 | AM2: 3.17 | AN2: 0 | AO2: 0 | AP2: 0 | AQ2: 0 | AR2: 0 | AS2: 0.895 | AT2: 0.943 | AU2: 13 | AV2: 10 | AW2: 4.99 | AX2: 16 | AY2: 25.5 | AZ2: 28.795 | BA2: 27.148 | BB2: 25.751 | BC2: 0.777 | BD2: 0.878 | BE2: 0.827 | BF2: 23.3 | BG2: 0.71 | BH2: 0.958 | BI2: 105.51 | BJ2: 24.419 | BK2: 0.744 | BL2: -0.148 | BM2: -2.2 | BN2: 3.7 | BO2: -3.295 | BP2: 126 | BQ2: 59 | BR2: 30 | BS2: 213 | BT2: 6.492 | BU2: 3 | BV2: 3 | BW2: 2.67 | BX2: 5.508 | BY2: 4.089 | BZ2: 0.125 | CA2: 31.237 | CB2: 0.952 | CC2: 25 | CD2: 9 | CE2: 25 | CF2: 1 | CG2: 6 | CI2: 32.735 | CJ2: 5.164 | CK2: 48 | CL2: 41 | CM2: 15 | CN2: 9 | CO2: 5 | CP2: 42 | CQ2: 1 | CR2: 130 | CS2: 73 | CT2: 0.4 | CW2: 38.6 | CX2: 1.176 | CY2: 0 | DB2: 0 | DE2: 7.68 | DF2: 2 | DG2: 0 | DH2: 24 | DI2: 25 | DL2: 17 | DM2: 23 | DN2: 5 | DO2: 73.4 | DP2: 249.31 | DQ2: 124.38 | DR2: 248.76 | DS2: 0.55 | DT2: 3204 | DU2: 84.31 | DV2: flat | DW2: 1.23 | DX2: 1.1 | DY2: 1.06 | DZ2: -0.17 | EA2: 1473 | EB2: 3.32 | EC2: 0.5 | ED2: 113.33 | EE2: 3095 | EF2: TRUE | EG2: 99.7 | EH2: 36.3 | EI2: 1 | EJ2: 23.4 | EK2: 13.9 | EL2: 118.1 | EM2: 108.8 | EN2: 722.2 | EO2: 94.5 | EP2: 12.4
A3: Bruno Fernandes | B3: MUN | C3: MID | D3: MID | E3: 12 | F3: TRUE | G3: TRUE | H3: 32 | I3: a | L3: p141746 | M3: 426 | N3: 1 | O3: 1 | P3: 1 | Q3: 3065 | R3: 35 | S3: 35 | T3: 34.056 | U3: 87.6 | V3: 235 | W3: 6.9 | X3: 9 | Y3: 24 | Z3: 21 | AA3: 7 | AB3: 46 | AC3: 41 | AD3: 43 | AE3: 2 | AF3: 1008 | AG3: 994 | AH3: -14 | AI3: 237 | AJ3: 0.174 | AK3: 0.211 | AL3: 287 | AM3: 8.427 | AN3: 5 | AO3: 10 | AP3: 0.143 | AQ3: 0.314 | AR3: 0.143 | AS3: 0.921 | AT3: 0.971 | AU3: 8 | AV3: 12 | AW3: 4.67 | AX3: 18 | AY3: 10.79 | AZ3: 11.932 | BA3: 11.361 | BB3: 7.365 | BC3: 0.317 | BD3: 0.35 | BE3: 0.334 | BF3: 9.1 | BG3: 0.267 | BH3: 0.954 | BI3: 39.78 | BJ3: 10.298 | BK3: 0.302 | BL3: -2.361 | BM3: -1.69 | BN3: -0.1 | BO3: -1.142 | BP3: 85 | BQ3: 24 | BR3: 8 | BS3: 91 | BT3: 2.672 | BU3: 4 | BW3: 12.28 | BX3: 17.757 | BY3: 15.019 | BZ3: 0.441 | CA3: 26.379 | CB3: 0.775 | CC3: 137 | CD3: 33 | CE3: 136 | CF3: 55 | CG3: 15 | CH3: 90 | CI3: 25.944 | CJ3: 11.664 | CK3: 67 | CL3: 167 | CM3: 53 | CN3: 32 | CO3: 20 | CP3: 42 | CQ3: 5 | CR3: 124 | CS3: 21 | CT3: 0.5 | CV3: 3 | CW3: 44.42 | CX3: 1.304 | CY3: 0 | DB3: 0 | DE3: 8.03 | DF3: 5 | DG3: 0 | DH3: 25 | DI3: 35 | DK3: 1 | DL3: 15 | DM3: 30 | DN3: 4 | DO3: 48 | DP3: 226.84 | DQ3: 113.42 | DR3: 226.84 | DS3: 0 | DT3: 3342 | DU3: 87.96 | DV3: flat | DW3: 2.46 | DX3: 2.27 | DY3: 2.32 | DZ3: -0.14 | EA3: 1455 | EB3: 3.12 | EC3: 0.5 | ED3: 102.67 | EE3: 3114 | EF3: TRUE | EG3: 99.9 | EH3: 36 | EI3: 2 | EJ3: 36.1 | EK3: 33.7 | EL3: 22.5 | EM3: 269.8 | EN3: 204.1 | EO3: 116.2 | EP3: 13
A4: Gabriel Magalhães | B4: ARS | C4: DEF | D4: DEF | E4: 8 | F4: TRUE | G4: TRUE | H4: 28.7 | I4: a | L4: p226597 | M4: 4 | Q4: 2750 | R4: 32 | S4: 30 | T4: 30.556 | U4: 85.9 | V4: 209 | W4: 6.84 | X4: 3 | Y4: 5 | Z4: 4 | AA4: 18 | AB4: 20 | AC4: 30 | AD4: 24 | AE4: -6 | AF4: 724 | AG4: 683 | AH4: -41 | AI4: 203 | AJ4: 0.144 | AK4: 0.168 | AL4: 277 | AM4: 9.065 | AN4: 11 | AO4: 22 | AP4: 0.367 | AQ4: 0.367 | AR4: 0.233 | AS4: 0.789 | AT4: 0.938 | AU4: 8 | AV4: 6 | AW4: 4.43 | AX4: 15 | AY4: 2.94 | AZ4: 4.649 | BA4: 3.795 | BB4: 4.649 | BC4: 0.096 | BD4: 0.152 | BE4: 0.124 | BF4: 2.4 | BG4: 0.079 | BH4: 0.816 | BI4: 15.16 | BJ4: 2.399 | BK4: 0.079 | BL4: -0.795 | BM4: -0.54 | BN4: 0.6 | BO4: -1.709 | BP4: 27 | BQ4: 7 | BR4: 4 | BS4: 46 | BT4: 1.505 | BV4: 1 | BW4: 1.75 | BX4: 2.725 | BY4: 2.238 | BZ4: 0.073 | CA4: 6.032 | CB4: 0.197 | CC4: 7 | CD4: 5 | CE4: 7 | CF4: 1 | CG4: 2 | CI4: 8.894 | CJ4: 8.31 | CK4: 239 | CL4: 64 | CM4: 38 | CN4: 20 | CO4: 23 | CP4: 182 | CQ4: 34 | CR4: 171 | CS4: 99 | CT4: 0.1 | CU4: 1 | CV4: 2 | CW4: 22.01 | CX4: 0.72 | CY4: 0 | DB4: 0 | DE4: 7.32 | DF4: 4 | DG4: 0 | DH4: 21 | DI4: 34 | DL4: 1 | DM4: 4 | DN4: 0 | DO4: 27.2 | DP4: 185.19 | DQ4: 92.85 | DR4: 185.7 | DS4: -0.51 | DT4: 3283 | DU4: 86.4 | DV4: flat | DW4: 7.56 | DX4: 6.97 | DY4: 8.04 | DZ4: 0.48 | EA4: 1475 | EB4: 5.06 | EC4: 1 | ED4: 117.33 | EE4: 3242 | EF4: TRUE | EG4: 99.8 | EH4: 33.4 | EI4: 7 | EJ4: 101.9 | EK4: 59.8 | EL4: 392.9 | EM4: 724.7 | EN4: 1229 | EO4: 455.9 | EP4: 13.2
A5: Antoine Semenyo | B5: MCI | C5: MID | D5: MID | E5: 8.5 | F5: TRUE | G5: TRUE | H5: 26.6 | I5: a | L5: p437730 | M5: 397 | N5: 3 | Q5: 3200 | R5: 37 | S5: 37 | T5: 35.556 | U5: 86.5 | V5: 202 | W5: 5.681 | X5: 17 | Y5: 6 | Z5: 4 | AA5: 12 | AB5: 52 | AC5: 18 | AD5: 19 | AE5: 1 | AF5: 678 | AG5: 672 | AH5: -6 | AI5: 203 | AJ5: 0.089 | AK5: 0.098 | AL5: 236 | AM5: 6.637 | AN5: 3 | AO5: 6 | AP5: 0.081 | AQ5: 0.108 | AR5: 0.081 | AS5: 0.974 | AT5: 0.946 | AU5: 12 | AV5: 5 | AW5: 4.32 | AX5: 18 | AY5: 11.1 | AZ5: 12.837 | BA5: 11.968 | BB5: 11.314 | BC5: 0.312 | BD5: 0.361 | BE5: 0.337 | BF5: 13 | BG5: 0.366 | BH5: 1.141 | BI5: 25.66 | BJ5: 12.663 | BK5: 0.356 | BL5: 5.032 | BM5: 1.9 | BN5: 4 | BO5: -1.737 | BP5: 83 | BQ5: 41 | BR5: 7 | BS5: 176 | BT5: 4.95 | BU5: 1 | BW5: 3.12 | BX5: 4.13 | BY5: 3.625 | BZ5: 0.102 | CA5: 15.593 | CB5: 0.439 | CC5: 38 | CD5: 8 | CE5: 39 | CF5: 8 | CG5: 2 | CI5: 20.871 | CJ5: 7.894 | CK5: 49 | CL5: 142 | CM5: 45 | CN5: 32 | CO5: 13 | CP5: 29 | CQ5: 7 | CR5: 184 | CS5: 59 | CT5: 0.7 | CV5: 2 | CW5: 47.67 | CX5: 1.341 | CY5: 0 | DB5: 0 | DE5: 7.34 | DF5: 7 | DG5: 0 | DH5: 56 | DI5: 21 | DK5: 1 | DL5: 59 | DM5: 63 | DN5: 19 | DO5: 27.5 | DP5: 182.2 | DQ5: 91.1 | DR5: 182.2 | DS5: 0 | DT5: 3106 | DU5: 81.75 | DV5: flat | DW5: 7.24 | DX5: 6.55 | DY5: 6.75 | DZ5: -0.49 | EA5: 1512 | EB5: 5.9 | EC5: 0.8 | ED5: 101.33 | EE5: 3116 | EF5: TRUE | EG5: 99.9 | EH5: 36 | EI5: 6 | EJ5: 38.6 | EK5: 18.2 | EL5: 82.1 | EM5: 267.4 | EN5: 882.7 | EO5: 205.2 | EP5: 15.8
A6: Morgan Gibbs-White | B6: NFO | C6: MID | D6: MID | E6: 8 | F6: TRUE | G6: TRUE | H6: 26.6 | I6: a | L6: p222531 | M6: 480 | N6: 2 | P6: 1 | Q6: 3101 | R6: 37 | S6: 35 | T6: 34.456 | U6: 83.8 | V6: 188 | W6: 5.456 | X6: 15 | Y6: 4 | Z6: 4 | AA6: 10 | AB6: 45 | AC6: 18 | AD6: 18 | AE6: 0 | AF6: 712 | AG6: 702 | AH6: -10 | AI6: 188 | AJ6: 0.096 | AK6: 0.106 | AL6: 178 | AM6: 5.166 | AN6: 1 | AO6: 2 | AP6: 0.029 | AQ6: 0.029 | AR6: 0.029 | AS6: 0.921 | AT6: 0.946 | AU6: 15 | AV6: 3 | AW6: 4.06 | AX6: 20 | AY6: 10.81 | AZ6: 11.672 | BA6: 11.241 | BB6: 10.911 | BC6: 0.314 | BD6: 0.339 | BE6: 0.326 | BF6: 12.9 | BG6: 0.374 | BH6: 0.989 | BI6: 30.54 | BJ6: 10.687 | BK6: 0.31 | BL6: 3.759 | BM6: 2.09 | BN6: 2.1 | BO6: -0.862 | BP6: 83 | BQ6: 32 | BR6: 10 | BS6: 126 | BT6: 3.657 | BU6: 1 | BV6: 3 | BW6: 2.91 | BX6: 4.504 | BY6: 3.707 | BZ6: 0.108 | CA6: 14.948 | CB6: 0.434 | CC6: 48 | CD6: 5 | CE6: 49 | CF6: 9 | CG6: 1 | CH6: 1 | CI6: 17.265 | CJ6: 5.414 | CK6: 48 | CL6: 110 | CM6: 20 | CN6: 15 | CO6: 13 | CP6: 32 | CQ6: 3 | CR6: 130 | CS6: 41 | CT6: 0.6 | CU6: 1 | CV6: 4 | CW6: 49.7 | CX6: 1.442 | CY6: 0 | DB6: 0 | DE6: 7.15 | DF6: 1 | DG6: 0 | DH6: 26 | DI6: 41 | DJ6: 1 | DL6: 30 | DM6: 37 | DN6: 5 | DO6: 11.6 | DP6: 182.08 | DQ6: 91.04 | DR6: 182.08 | DS6: 0 | DT6: 3301 | DU6: 86.86 | DV6: flat | DW6: 17.37 | DX6: 14.7 | DY6: 17.33 | DZ6: -0.03 | EA6: 1268 | EB6: 11.79 | EC6: 1.33 | ED6: 118.67 | EE6: 2152 | EF6: TRUE | EG6: 99.9 | EH6: 55.8 | EI6: 8 | EJ6: 37.4 | EK6: 24.6 | EL6: 63.3 | EM6: 275.9 | EN6: 836.5 | EO6: 207.5 | EP6: 16.5
A7: Declan Rice | B7: ARS | C7: MID | D7: MID | E7: 7.5 | F7: TRUE | G7: TRUE | H7: 27.6 | I7: a | L7: p204480 | M7: 13 | O7: 1 | P7: 1 | Q7: 3093 | R7: 36 | S7: 35 | T7: 34.367 | U7: 85.9 | V7: 184 | W7: 5.354 | X7: 4 | Y7: 9 | Z7: 5 | AA7: 18 | AB7: 25 | AC7: 23 | AD7: 24 | AE7: 1 | AF7: 790 | AG7: 769 | AH7: -21 | AI7: 185 | AJ7: 0.125 | AK7: 0.143 | AL7: 376 | AM7: 10.941 | AN7: 14 | AO7: 28 | AP7: 0.4 | AQ7: 0.6 | AR7: 0.4 | AS7: 0.921 | AT7: 0.972 | AU7: 6 | AV7: 4 | AW7: 3.59 | AX7: 17 | AY7: 3.15 | AZ7: 3.721 | BA7: 3.435 | BB7: 3.721 | BC7: 0.092 | BD7: 0.108 | BE7: 0.1 | BF7: 4.5 | BG7: 0.131 | BH7: 1.132 | BI7: 12.59 | BJ7: 3.565 | BK7: 0.104 | BL7: 0.565 | BM7: 1.35 | BN7: -0.5 | BO7: -0.571 | BP7: 40 | BQ7: 13 | BR7: 3 | BS7: 56 | BT7: 1.629 | BV7: 1 | BW7: 7.32 | BX7: 8.159 | BY7: 7.74 | BZ7: 0.225 | CA7: 11.175 | CB7: 0.325 | CC7: 63 | CD7: 17 | CE7: 63 | CF7: 47 | CG7: 5 | CH7: 95 | CI7: 18.491 | CJ7: 12.957 | CK7: 127 | CL7: 180 | CM7: 69 | CN7: 35 | CO7: 37 | CP7: 78 | CQ7: 12 | CR7: 145 | CS7: 50 | CT7: 0.3 | CU7: 1 | CW7: 23.87 | CX7: 0.695 | CY7: 0 | DB7: 0 | DE7: 7.56 | DF7: 3 | DG7: 0 | DH7: 26 | DI7: 11 | DL7: 14 | DM7: 18 | DN7: 1 | DO7: 21.6 | DP7: 152.45 | DQ7: 75.39 | DR7: 150.78 | DS7: 1.67 | DT7: 3106 | DU7: 81.75 | DV7: flat | DW7: 15.01 | DX7: 14.33 | DY7: 15.11 | DZ7: 0.1 | EA7: 1509 | EB7: 8.43 | EC7: 1.14 | ED7: 110.67 | EE7: 3060 | EF7: TRUE | EG7: 99.9 | EH7: 37.1 | EI7: 13 | EJ7: 77.3 | EK7: 55.2 | EL7: 49.1 | EM7: 900.3 | EN7: 399.6 | EO7: 276.8 | EP7: 16.8
A8: Igor Thiago | B8: BRE | C8: FWD | D8: FWD | E8: 8 | F8: TRUE | G8: TRUE | H8: 25.2 | I8: a | L8: p502500 | M8: 106 | N8: 1 | Q8: 3282 | R8: 38 | S8: 37 | T8: 36.467 | U8: 86.4 | V8: 181 | W8: 4.963 | X8: 22 | Y8: 1 | Z8: 1 | AA8: 10 | AB8: 50 | AC8: 22 | AD8: 22 | AE8: 0 | AF8: 710 | AG8: 694 | AH8: -16 | AI8: 181 | AJ8: 0.122 | AK8: 0.138 | AL8: 214 | AM8: 5.868 | AN8: 1 | AO8: 2 | AP8: 0.027 | AQ8: 0.054 | AR8: 0.027 | AS8: 0.974 | AT8: 0.974 | AU8: 21 | AV8: 6 | AW8: 4.26 | AX8: 17 | AY8: 20.6 | AZ8: 24.69 | BA8: 22.645 | BB8: 17.839 | BC8: 0.565 | BD8: 0.677 | BE8: 0.621 | BF8: 20.1 | BG8: 0.551 | BH8: 0.978 | BI8: 20.73 | BJ8: 20.148 | BK8: 0.553 | BL8: -0.645 | BM8: -0.5 | BN8: 1.9 | BO8: -4.09 | BP8: 84 | BQ8: 43 | BR8: 20 | BS8: 169 | BT8: 4.634 | BU8: 8 | BV8: 2 | BW8: 1.83 | BX8: 3.45 | BY8: 2.64 | BZ8: 0.072 | CA8: 25.285 | CB8: 0.693 | CC8: 24 | CD8: 6 | CE8: 24 | CF8: 7 | CG8: 2 | CI8: 22.693 | CJ8: 4.928 | CK8: 84 | CL8: 93 | CM8: 37 | CN8: 22 | CO8: 12 | CP8: 64 | CQ8: 8 | CR8: 203 | CS8: 112 | CT8: 0.4 | CV8: 2 | CW8: 53.17 | CX8: 1.458 | CY8: 0 | DB8: 0 | DE8: 7.14 | DF8: 7 | DG8: 0 | DH8: 73 | DI8: 26 | DL8: 29 | DM8: 42 | DN8: 23 | DO8: 16.1 | DP8: 167.6 | DQ8: 83.8 | DR8: 167.6 | DS8: 0 | DT8: 3209 | DU8: 84.45 | DV8: flat | DW8: 12.17 | DX8: 10.77 | DY8: 11.56 | DZ8: -0.61 | EA8: 1522 | EB8: 8.58 | EC8: 0.5 | ED8: 114.67 | EE8: 2989 | EF8: TRUE | EG8: 99.9 | EH8: 38.6 | EI8: 9 | EJ8: 39.1 | EK8: 19.4 | EL8: 136.8 | EM8: 144.9 | EN8: 1243.2 | EO8: 129.8 | EP8: 18.1
A9: Elliot Anderson | B9: MCI | C9: MID | D9: MID | E9: 6.5 | F9: TRUE | G9: TRUE | H9: 23.8 | I9: a | L9: p215379 | M9: 481 | O9: 3 | Q9: 3332 | R9: 38 | S9: 37 | T9: 37.022 | U9: 87.7 | V9: 180 | W9: 4.862 | X9: 4 | Y9: 5 | Z9: 4 | AA9: 10 | AB9: 50 | AC9: 16 | AD9: 18 | AE9: 2 | AF9: 795 | AG9: 775 | AH9: -20 | AI9: 182 | AJ9: 0.089 | AK9: 0.098 | AL9: 515 | AM9: 13.911 | AN9: 26 | AO9: 52 | AP9: 0.703 | AQ9: 0.892 | AR9: 0.703 | AS9: 0.974 | AT9: 0.974 | AU9: 10 | AV9: 3 | AW9: 3.01 | AX9: 12 | AY9: 2.94 | AZ9: 3.444 | BA9: 3.192 | BB9: 2.683 | BC9: 0.079 | BD9: 0.093 | BE9: 0.086 | BF9: 2.4 | BG9: 0.065 | BH9: 0.902 | BI9: 7.75 | BJ9: 2.651 | BK9: 0.072 | BL9: 0.808 | BM9: -0.54 | BN9: 1.6 | BO9: -0.504 | BP9: 44 | BQ9: 10 | BR9: 1 | BS9: 62 | BT9: 1.675 | BU9: 1 | BW9: 4.79 | BX9: 4.843 | BY9: 4.816 | BZ9: 0.13 | CA9: 8.008 | CB9: 0.216 | CC9: 55 | CD9: 9 | CE9: 54 | CF9: 51 | CG9: 2 | CH9: 87 | CI9: 16.283 | CJ9: 11.958 | CK9: 106 | CL9: 306 | CM9: 103 | CN9: 63 | CO9: 41 | CP9: 49 | CQ9: 16 | CR9: 297 | CS9: 66 | CT9: 0.7 | CV9: 4 | CW9: 53.65 | CX9: 1.449 | CY9: 0 | DB9: 0 | DE9: 7.51 | DF9: 8 | DG9: 0 | DH9: 57 | DI9: 80 | DK9: 1 | DL9: 50 | DM9: 62 | DN9: 2 | DO9: 11.1 | DP9: 116.9 | DQ9: 63.21 | DR9: 126.42 | DS9: -9.52 | DT9: 2096 | DU9: 55.17 | DV9: flat | DW9: 33.68 | DX9: 31.37 | DY9: 34.6 | DZ9: 0.92 | EA9: 1544 | EB9: 16.01 | EC9: 1.6 | ED9: 113.14 | EE9: 3363 | EF9: TRUE | EG9: 98.9 | EH9: 30.2 | EI9: 31 | EJ9: 75.7 | EK9: 53.7 | EL9: 61.7 | EM9: 1043.8 | EN9: 691.8 | EO9: 416.1 | EP9: 18.5
A10: Marc Guéhi | B10: MCI | C10: DEF | D10: DEF | E10: 6 | F10: TRUE | G10: TRUE | H10: 26.1 | I10: a | L10: p209036 | M10: 388 | Q10: 3150 | R10: 35 | S10: 35 | T10: 35 | U10: 90 | V10: 179 | W10: 5.114 | X10: 3 | Y10: 5 | Z10: 3 | AA10: 14 | AB10: 35 | AC10: 14 | AD10: 12 | AE10: -2 | AF10: 688 | AG10: 647 | AH10: -41 | AI10: 177 | AJ10: 0.078 | AK10: 0.085 | AL10: 278 | AM10: 7.943 | AN10: 11 | AO10: 22 | AP10: 0.314 | AQ10: 0.314 | AR10: 0.114 | AS10: 0.921 | AT10: 1 | AU10: 12 | AV10: 4 | AW10: 4 | AX10: 15 | AY10: 4.05 | AZ10: 4.697 | BA10: 4.374 | BB10: 4.697 | BC10: 0.116 | BD10: 0.134 | BE10: 0.125 | BF10: 4 | BG10: 0.114 | BH10: 1.084 | BI10: 7.96 | BJ10: 4.39 | BK10: 0.125 | BL10: -1.374 | BM10: -0.05 | BN10: -1 | BO10: -0.647 | BP10: 32 | BQ10: 9 | BR10: 6 | BS10: 62 | BT10: 1.771 | BV10: 1 | BW10: 2.37 | BX10: 2.727 | BY10: 2.548 | BZ10: 0.073 | CA10: 6.922 | CB10: 0.198 | CC10: 18 | CD10: 5 | CE10: 18 | CF10: 3 | CG10: 3 | CH10: 2 | CI10: 17.673 | CJ10: 15.488 | CK10: 232 | CL10: 139 | CM10: 46 | CN10: 31 | CO10: 50 | CP10: 164 | CQ10: 23 | CR10: 194 | CS10: 103 | CT10: 0.1 | CU10: 2 | CV10: 0 | CW10: 44.58 | CX10: 1.274 | CY10: 0 | DB10: 0 | DE10: 7.37 | DF10: 6 | DG10: 0 | DH10: 25 | DI10: 38 | DJ10: 1 | DL10: 7 | DM10: 18 | DO10: 22.6 | DP10: 116.75 | DQ10: 58.17 | DR10: 116.34 | DS10: 0.41 | DT10: 2611 | DU10: 68.7 | DV10: flat | DW10: 32.73 | DX10: 34.4 | DY10: 29.35 | DZ10: -3.38 | EA10: 1622 | EB10: 11.58 | EC10: 1 | ED10: 100 | EE10: 3874 | EF10: TRUE | EG10: 99.9 | EH10: 20.5 | EI10: 56 | EJ10: 98.4 | EK10: 50.8 | EL10: 175 | EM10: 720.2 | EN10: 1236.1 | EO10: 455.1 | EP10: 17.6
A11: João Pedro | B11: CHE | C11: FWD | D11: FWD | E11: 7.5 | F11: TRUE | G11: TRUE | H11: 24.9 | I11: a | L11: p475168 | M11: 165 | Q11: 2658 | R11: 35 | S11: 31 | T11: 29.533 | U11: 75.9 | V11: 177 | W11: 5.993 | X11: 15 | Y11: 9 | Z11: 5 | AA11: 10 | AB11: 36 | AC11: 30 | AD11: 30 | AE11: 0 | AF11: 715 | AG11: 710 | AH11: -5 | AI11: 177 | AJ11: 0.169 | AK11: 0.204 | AL11: 138 | AM11: 4.673 | AN11: 0 | AO11: 0 | AP11: 0 | AQ11: 0.032 | AR11: 0 | AS11: 0.816 | AT11: 0.857 | AU11: 20 | AV11: 5 | AW11: 4.56 | AX11: 19 | AY11: 14.91 | AZ11: 15.724 | BA11: 15.317 | BB11: 15.724 | BC11: 0.505 | BD11: 0.532 | BE11: 0.519 | BF11: 15.2 | BG11: 0.515 | BH11: 1.003 | BI11: 35.88 | BJ11: 14.951 | BK11: 0.506 | BL11: -0.317 | BM11: 0.29 | BN11: -0.2 | BO11: -0.814 | BP11: 73 | BQ11: 28 | BR11: 12 | BS11: 145 | BT11: 4.91 | BV11: 3 | BW11: 1.96 | BX11: 3.984 | BY11: 2.972 | BZ11: 0.101 | CA11: 18.289 | CB11: 0.619 | CC11: 29 | CD11: 6 | CE11: 29 | CF11: 1 | CG11: 5 | CI11: 19.28 | CJ11: 4.796 | CK11: 39 | CL11: 72 | CM11: 27 | CN11: 18 | CO11: 7 | CP11: 27 | CQ11: 5 | CR11: 196 | CS11: 74 | CT11: 0.5 | CU11: 0 | CW11: 37.25 | CX11: 1.261 | CY11: 0 | DB11: 0 | DE11: 7.18 | DF11: 5 | DG11: 0 | DH11: 38 | DI11: 56 | DJ11: 3 | DL11: 40 | DM11: 55 | DN11: 16 | DO11: 55.9 | DP11: 176.3 | DQ11: 88.23 | DR11: 176.46 | DS11: -0.16 | DT11: 2890 | DU11: 76.05 | DV11: flat | DW11: 8.78 | DX11: 8.83 | DY11: 7.46 | DZ11: -1.33 | EA11: 1635 | EB11: 6.04 | EC11: 0.8 | ED11: 120 | EE11: 4154 | EF11: TRUE | EG11: 100 | EH11: 14.8 | EI11: 14 | EJ11: 36.4 | EK11: 18.3 | EL11: 91.7 | EM11: 173.5 | EN11: 894.4 | EO11: 145.3 | EP11: 15
A12: Virgil van Dijk | B12: LIV | C12: DEF | D12: DEF | E12: 6.5 | F12: TRUE | G12: TRUE | H12: 35.1 | I12: a | L12: p97032 | M12: 356 | Q12: 3420 | R12: 38 | S12: 38 | T12: 38 | U12: 90 | V12: 175 | W12: 4.605 | X12: 6 | Y12: 1 | AA12: 10 | AB12: 53 | AC12: 10 | AD12: 9 | AE12: -1 | AF12: 593 | AG12: 534 | AH12: -59 | AI12: 174 | AJ12: 0.057 | AK12: 0.061 | AL12: 352 | AM12: 9.263 | AN12: 16 | AO12: 32 | AP12: 0.421 | AQ12: 0.421 | AR12: 0.289 | AS12: 1 | AT12: 1 | AU12: 14 | AV12: 3 | AW12: 3.77 | AX12: 17 | AY12: 3.77 | AZ12: 4.891 | BA12: 4.331 | BB12: 4.891 | BC12: 0.099 | BD12: 0.129 | BE12: 0.114 | BF12: 4.9 | BG12: 0.129 | BH12: 0.991 | BI12: 11.37 | BJ12: 3.737 | BK12: 0.098 | BL12: 1.669 | BM12: 1.13 | BN12: 1.1 | BO12: -1.121 | BP12: 30 | BQ12: 14 | BR12: 8 | BS12: 71 | BT12: 1.868 | BV12: 5 | BW12: 1.44 | BX12: 0.329 | BY12: 0.884 | BZ12: 0.023 | CA12: 5.215 | CB12: 0.137 | CC12: 11 | CE12: 12 | CG12: 1 | CI12: 12.486 | CJ12: 11.383 | CK12: 329 | CL12: 87 | CM12: 23 | CN12: 13 | CO12: 28 | CP12: 275 | CQ12: 26 | CR12: 216 | CS12: 174 | CT12: 0.1 | CU12: 2 | CV12: 2 | CW12: 47.63 | CX12: 1.253 | CY12: 0 | DB12: 0 | DE12: 7.26 | DF12: 4 | DG12: 0 | DH12: 19 | DI12: 18 | DK12: 1 | DL12: 2 | DM12: 1 | DN12: 1 | DO12: 16.9 | DP12: 158.96 | DQ12: 79.48 | DR12: 158.96 | DS12: 0 | DT12: 3340 | DU12: 87.9 | DV12: flat | DW12: 24.92 | DX12: 25.44 | DY12: 23.63 | DZ12: -1.29 | EA12: 1617 | EB12: 9.39 | EC12: 0.8 | ED12: 88 | EE12: 3851 | EF12: TRUE | EG12: 99.9 | EH12: 20.9 | EI12: 32 | EJ12: 114 | EK12: 48.2 | EL12: 285 | EM12: 789.7 | EN12: 3867.6 | EO12: 655.8 | EP12: 19.5
A13: Marcos Senesi | B13: TOT | C13: DEF | D13: DEF | E13: 6 | F13: TRUE | G13: TRUE | H13: 29.3 | I13: a | L13: p221466 | M13: 498 | Q13: 3288 | R13: 37 | S13: 37 | T13: 36.533 | U13: 88.9 | V13: 175 | W13: 4.79 | X13: 0 | Y13: 6 | Z13: 5 | AA13: 11 | AB13: 53 | AC13: 14 | AD13: 12 | AE13: -2 | AF13: 571 | AG13: 508 | AH13: -63 | AI13: 173 | AJ13: 0.08 | AK13: 0.087 | AL13: 419 | AM13: 11.469 | AN13: 26 | AO13: 52 | AP13: 0.703 | AQ13: 0.703 | AR13: 0.432 | AS13: 0.974 | AT13: 1 | AU13: 13 | AV13: 4 | AW13: 3.58 | AX13: 14 | AY13: 1.53 | AZ13: 1.851 | BA13: 1.69 | BB13: 1.851 | BC13: 0.042 | BD13: 0.051 | BE13: 0.046 | BF13: 0.5 | BG13: 0.014 | BH13: 0.799 | BI13: 6.01 | BJ13: 1.223 | BK13: 0.033 | BL13: -1.69 | BM13: -1.03 | BN13: -0.5 | BO13: -0.321 | BP13: 17 | BQ13: 5 | BR13: 2 | BS13: 53 | BT13: 1.451 | BW13: 4.72 | BX13: 4.027 | BY13: 4.373 | BZ13: 0.12 | CA13: 6.064 | CB13: 0.166 | CC13: 24 | CD13: 7 | CE13: 24 | CF13: 8 | CG13: 10 | CI13: 14.265 | CJ13: 10.906 | CK13: 357 | CL13: 155 | CM13: 62 | CN13: 35 | CO13: 56 | CP13: 253 | CQ13: 47 | CR13: 196 | CS13: 92 | CT13: 0.1 | CV13: 2 | CW13: 54.77 | CX13: 1.499 | CY13: 0 | DB13: 0 | DE13: 7.19 | DF13: 8 | DG13: 0 | DH13: 34 | DI13: 37 | DJ13: 1 | DL13: 6 | DM13: 14 | DN13: 1 | DO13: 10.2 | DP13: 71.48 | DQ13: 35.74 | DR13: 71.48 | DS13: 0 | DT13: 1573 | DU13: 41.4 | DV13: flat | DW13: 49.73 | DX13: 48.99 | DY13: 49.65 | DZ13: -0.08 | EA13: 1488 | EB13: 16.74 | EC13: 9 | ED13: 119 | EE13: 2815 | EF13: TRUE | EG13: 98.9 | EH13: 41.6 | EI13: 57 | EJ13: 193.4 | EK13: 62 | EL13: 137 | EM13: 1945.2 | EN13: 751.8 | EO13: 542.2 | EP13: 18.8
A14: James Tarkowski | B14: EVE | C14: DEF | D14: DEF | E14: 6 | F14: TRUE | G14: TRUE | H14: 33.8 | I14: a | L14: p17761 | M14: 229 | Q14: 3330 | R14: 37 | S14: 37 | T14: 37 | U14: 90 | V14: 170 | W14: 4.595 | X14: 2 | Y14: 3 | Z14: 3 | AA14: 11 | AB14: 48 | AC14: 12 | AD14: 12 | AE14: 0 | AF14: 592 | AG14: 538 | AH14: -54 | AI14: 170 | AJ14: 0.071 | AK14: 0.076 | AL14: 376 | AM14: 10.162 | AN14: 22 | AO14: 44 | AP14: 0.595 | AQ14: 0.595 | AR14: 0.351 | AS14: 0.974 | AT14: 1 | AU14: 11 | AV14: 3 | AW14: 3.74 | AX14: 15 | AY14: 2.53 | AZ14: 2.869 | BA14: 2.7 | BB14: 2.869 | BC14: 0.068 | BD14: 0.078 | BE14: 0.073 | BF14: 3.2 | BG14: 0.086 | BH14: 0.812 | BI14: 9.37 | BJ14: 2.054 | BK14: 0.056 | BL14: -0.7 | BM14: 0.67 | BN14: -1.2 | BO14: -0.339 | BP14: 21 | BQ14: 10 | BR14: 4 | BS14: 84 | BT14: 2.27 | BV14: 1 | BW14: 2.1 | BX14: 2.057 | BY14: 2.078 | BZ14: 0.056 | CA14: 4.778 | CB14: 0.129 | CC14: 18 | CD14: 2 | CE14: 18 | CF14: 2 | CG14: 3 | CI14: 6.824 | CJ14: 5.569 | CK14: 325 | CL14: 90 | CM14: 51 | CN14: 29 | CO14: 32 | CP14: 242 | CQ14: 52 | CR14: 234 | CS14: 147 | CT14: 0.1 | CU14: 1 | CV14: 7 | CW14: 53.54 | CX14: 1.447 | CY14: 0 | DB14: 0 | DE14: 7.13 | DF14: 8 | DG14: 0 | DH14: 32 | DI14: 35 | DK14: 1 | DL14: 4 | DM14: 1 | DN14: 2 | DO14: 9.7 | DP14: 150.34 | DQ14: 75.17 | DR14: 150.34 | DS14: 0 | DT14: 3266 | DU14: 85.95 | DV14: flat | DW14: 48.45 | DX14: 48.13 | DY14: 47.51 | DZ14: -0.93 | EA14: 1519 | EB14: 15.58 | EC14: 5.33 | ED14: 118.67 | EE14: 3130 | EF14: TRUE | EG14: 99.6 | EH14: 35.5 | EI14: 58 | EJ14: 158.6 | EK14: 39.6 | EL14: 185 | EM14: 1233.5 | EN14: 1602.2 | EO14: 697 | EP14: 19.6
A15: Morgan Rogers | B15: CHE | C15: MID | D15: MID | E15: 7.5 | F15: TRUE | G15: TRUE | H15: 24.1 | I15: a | L15: p244850 | M15: 40 | Q15: 3280 | R15: 37 | S15: 37 | T15: 36.444 | U15: 88.6 | V15: 169 | W15: 4.637 | X15: 10 | Y15: 8 | Z15: 6 | AA15: 9 | AB15: 48 | AC15: 17 | AD15: 17 | AE15: 0 | AF15: 605 | AG15: 591 | AH15: -14 | AI15: 169 | AJ15: 0.101 | AK15: 0.112 | AL15: 230 | AM15: 6.311 | AN15: 1 | AO15: 2 | AP15: 0.027 | AQ15: 0.135 | AR15: 0.027 | AS15: 0.974 | AT15: 1 | AU15: 18 | AV15: 5 | AW15: 4.14 | AX15: 15 | AY15: 6.84 | AZ15: 7.146 | BA15: 6.993 | BB15: 7.146 | BC15: 0.188 | BD15: 0.196 | BE15: 0.192 | BF15: 8.1 | BG15: 0.222 | BH15: 1.116 | BI15: 14.68 | BJ15: 7.63 | BK15: 0.209 | BL15: 3.007 | BM15: 1.26 | BN15: 1.9 | BO15: -0.306 | BP15: 84 | BQ15: 32 | BR15: 4 | BS15: 181 | BT15: 4.966 | BW15: 4.32 | BX15: 7.475 | BY15: 5.898 | BZ15: 0.162 | CA15: 12.89 | CB15: 0.354 | CC15: 48 | CD15: 13 | CE15: 47 | CF15: 3 | CG15: 5 | CH15: 1 | CI15: 18.205 | CJ15: 7.18 | CK15: 49 | CL15: 139 | CM15: 42 | CN15: 23 | CO15: 13 | CP15: 32 | CQ15: 3 | CR15: 158 | CS15: 26 | CT15: 0.7 | CV15: 2 | CW15: 51.55 | CX15: 1.414 | CY15: 0 | DB15: 0 | DE15: 7 | DF15: 7 | DG15: 0 | DH15: 46 | DI15: 49 | DK15: 1 | DL15: 42 | DM15: 80 | DN15: 3 | DO15: 26.1 | DP15: 159.75 | DQ15: 79.57 | DR15: 159.14 | DS15: 0.61 | DT15: 2890 | DU15: 76.05 | DV15: flat | DW15: 16.73 | DX15: 15.52 | DY15: 16.45 | DZ15: -0.28 | EA15: 1499 | EB15: 9.31 | EC15: 1.14 | ED15: 114.67 | EE15: 3098 | EF15: TRUE | EG15: 99.9 | EH15: 36.4 | EI15: 15 | EJ15: 39 | EK15: 18.1 | EL15: 69.8 | EM15: 469 | EN15: 556.2 | EO15: 254.5 | EP15: 19.4
A16: Harry Wilson | B16: LEE | C16: MID | D16: MID | E16: 6.5 | F16: TRUE | G16: TRUE | H16: 29.4 | I16: a | L16: p153682 | M16: 260 | O16: 2 | Q16: 2674 | R16: 36 | S16: 32 | T16: 29.711 | U16: 74.3 | V16: 168 | W16: 5.654 | X16: 10 | Y16: 9 | Z16: 7 | AA16: 9 | AB16: 38 | AC16: 21 | AD16: 21 | AE16: 0 | AF16: 637 | AG16: 624 | AH16: -13 | AI16: 168 | AJ16: 0.125 | AK16: 0.143 | AL16: 177 | AM16: 5.957 | AN16: 1 | AO16: 2 | AP16: 0.031 | AQ16: 0.062 | AR16: 0.031 | AS16: 0.842 | AT16: 0.833 | AU16: 18 | AV16: 5 | AW16: 3.94 | AX16: 16 | AY16: 5.88 | AZ16: 5.76 | BA16: 5.82 | BB16: 5.76 | BC16: 0.198 | BD16: 0.194 | BE16: 0.196 | BF16: 8.9 | BG16: 0.3 | BH16: 1.236 | BI16: 15.55 | BJ16: 7.266 | BK16: 0.245 | BL16: 4.18 | BM16: 3.02 | BN16: 1.1 | BO16: 0.12 | BP16: 78 | BQ16: 25 | BR16: 1 | BS16: 105 | BT16: 3.534 | BW16: 4.77 | BX16: 5.504 | BY16: 5.137 | BZ16: 0.173 | CA16: 10.957 | CB16: 0.369 | CC16: 37 | CD16: 8 | CE16: 39 | CF16: 32 | CG16: 6 | CH16: 70 | CI16: 11.092 | CJ16: 4.133 | CK16: 66 | CL16: 82 | CM16: 29 | CN16: 19 | CO16: 15 | CP16: 48 | CQ16: 3 | CR16: 89 | CS16: 5 | CT16: 0.3 | CV16: 2 | CW16: 40.14 | CX16: 1.351 | CY16: 0 | DB16: 0 | DE16: 7.14 | DF16: 7 | DG16: 0 | DH16: 13 | DI16: 37 | DL16: 18 | DM16: 23 | DN16: 13 | DO16: 7.9 | DP16: 146.08 | DQ16: 73.04 | DR16: 146.08 | DS16: 0 | DT16: 2810 | DU16: 73.95 | DV16: flat | DW16: 46.77 | DX16: 43.66 | DY16: 47.42 | DZ16: 0.65 | EA16: 1411 | EB16: 20.28 | EC16: 0.8 | ED16: 120 | EE16: 2610 | EF16: TRUE | EG16: 96.7 | EH16: 44.6 | EI16: 33 | EJ16: 34.3 | EK16: 25.5 | EL16: 68.6 | EM16: 459.5 | EN16: 520.6 | EO16: 244.1 | EP16: 15.9
A17: Ollie Watkins | B17: AVL | C17: FWD | D17: FWD | E17: 8 | F17: TRUE | G17: TRUE | H17: 30.6 | I17: a | L17: p178301 | M17: 55 | N17: 2 | Q17: 2833 | R17: 37 | S17: 33 | T17: 31.478 | U17: 76.6 | V17: 167 | W17: 5.305 | X17: 16 | Y17: 4 | Z17: 3 | AA17: 9 | AB17: 38 | AC17: 26 | AD17: 26 | AE17: 0 | AF17: 623 | AG17: 618 | AH17: -5 | AI17: 167 | AJ17: 0.156 | AK17: 0.184 | AL17: 94 | AM17: 2.986 | AN17: 0 | AO17: 0 | AP17: 0 | AQ17: 0 | AR17: 0 | AS17: 0.868 | AT17: 0.865 | AU17: 24 | AV17: 5 | AW17: 4.42 | AX17: 16 | AY17: 15.4 | AZ17: 18.828 | BA17: 17.114 | BB17: 18.828 | BC17: 0.489 | BD17: 0.598 | BE17: 0.544 | BF17: 15.8 | BG17: 0.502 | BH17: 1.025 | BI17: 63.41 | BJ17: 15.786 | BK17: 0.501 | BL17: -1.114 | BM17: 0.4 | BN17: 0.2 | BO17: -3.428 | BP17: 83 | BQ17: 38 | BR17: 19 | BS17: 177 | BT17: 5.623 | BV17: 4 | BW17: 1.18 | BX17: 2.816 | BY17: 1.998 | BZ17: 0.063 | CA17: 19.112 | CB17: 0.607 | CC17: 23 | CD17: 4 | CE17: 23 | CF17: 2 | CH17: 0 | CI17: 21.746 | CJ17: 4.341 | CK17: 23 | CL17: 49 | CM17: 22 | CN17: 14 | CO17: 6 | CP17: 15 | CQ17: 2 | CR17: 116 | CS17: 36 | CT17: 0.5 | CW17: 43.39 | CX17: 1.378 | CY17: 0 | DB17: 0 | DE17: 6.97 | DF17: 4 | DG17: 0 | DH17: 35 | DI17: 32 | DJ17: 0 | DL17: 26 | DM17: 43 | DN17: 24 | DO17: 12.6 | DP17: 167.14 | DQ17: 83.7 | DR17: 167.4 | DS17: -0.26 | DT17: 2679 | DU17: 70.5 | DV17: flat | DW17: 13.66 | DX17: 11.89 | DY17: 12.81 | DZ17: -0.85 | EA17: 1497 | EB17: 9.36 | EC17: 1 | ED17: 112 | EE17: 2853 | EF17: TRUE | EG17: 99.9 | EH17: 41.4 | EI17: 10 | EJ17: 34.1 | EK17: 16 | EL17: 123.2 | EM17: 165.5 | EN17: 1417.9 | EO17: 148.2 | EP17: 17
A18: Adrien Truffert | B18: BOU | C18: DEF | D18: DEF | E18: 5.5 | F18: TRUE | G18: TRUE | H18: 24.8 | I18: a | L18: p494521 | M18: 61 | Q18: 3378 | R18: 38 | S18: 38 | T18: 37.533 | U18: 88.9 | V18: 165 | W18: 4.396 | X18: 1 | Y18: 6 | Z18: 5 | AA18: 11 | AB18: 51 | AC18: 19 | AD18: 19 | AE18: 0 | AF18: 607 | AG18: 567 | AH18: -40 | AI18: 165 | AJ18: 0.115 | AK18: 0.13 | AL18: 301 | AM18: 8.02 | AN18: 12 | AO18: 24 | AP18: 0.316 | AQ18: 0.316 | AR18: 0.132 | AS18: 1 | AT18: 1 | AU18: 12 | AV18: 3 | AW18: 3.1 | AX18: 11 | AY18: 1.35 | AZ18: 1.989 | BA18: 1.669 | BB18: 1.989 | BC18: 0.036 | BD18: 0.053 | BE18: 0.044 | BF18: 1.6 | BG18: 0.043 | BH18: 1.027 | BI18: 1.35 | BJ18: 1.386 | BK18: 0.037 | BL18: -0.669 | BM18: 0.25 | BN18: -0.6 | BO18: -0.639 | BP18: 16 | BQ18: 6 | BR18: 1 | BS18: 53 | BT18: 1.412 | BW18: 3.07 | BX18: 4.408 | BY18: 3.739 | BZ18: 0.1 | CA18: 5.408 | CB18: 0.144 | CC18: 33 | CD18: 4 | CE18: 32 | CF18: 34 | CH18: 1 | CI18: 15.239 | CJ18: 9.959 | CK18: 199 | CL18: 188 | CM18: 102 | CN18: 52 | CO18: 48 | CP18: 143 | CQ18: 10 | CR18: 212 | CS18: 44 | CT18: 0.2 | CU18: 1 | CV18: 2 | CW18: 54.42 | CX18: 1.45 | CY18: 0 | DB18: 0 | DE18: 7.18 | DF18: 5 | DG18: 0 | DH18: 39 | DI18: 32 | DL18: 33 | DM18: 24 | DO18: 4.9 | DP18: 140.24 | DQ18: 70.12 | DR18: 140.24 | DS18: 0 | DT18: 3266 | DU18: 85.95 | DV18: flat | DW18: 65.5 | DX18: 65.42 | DY18: 65.06 | DZ18: -0.44 | EA18: 1441 | EB18: 17.67 | EC18: 8 | ED18: 120 | EE18: 2497 | EF18: TRUE | EG18: 97.9 | EH18: 47.7 | EI18: 111 | EJ18: 211.1 | EK18: 63.7 | EL18: 105.6 | EM18: 2023.5 | EN18: 903.4 | EO18: 624.6 | EP18: 20.5
A19: David Raya | B19: ARS | C19: GKP | D19: GKP | E19: 6 | F19: TRUE | G19: TRUE | H19: 30.9 | I19: a | L19: p154561 | M19: 1 | Q19: 3330 | R19: 37 | S19: 37 | T19: 37 | U19: 90 | V19: 162 | W19: 4.378 | X19: 0 | Y19: 0 | AA19: 19 | AB19: 26 | AC19: 11 | AD19: 11 | AE19: 0 | AF19: 633 | AG19: 624 | AH19: -9 | AI19: 162 | AJ19: 0.068 | AK19: 0.073 | AL19: 0 | AM19: 0 | AN19: 0 | AO19: 0 | AP19: 0 | AQ19: 0 | AR19: 0 | AS19: 0.974 | AT19: 1 | AU19: 15 | AV19: 2 | AW19: 2.79 | AX19: 10 | AY19: 0 | AZ19: 0 | BA19: 0 | BB19: 0 | BC19: 0 | BD19: 0 | BE19: 0 | BH19: 0.986 | BI19: 0.11 | BJ19: 0 | BK19: 0 | BL19: 0 | BO19: 0 | BW19: 0.07 | BX19: 0.149 | BY19: 0.11 | BZ19: 0.003 | CA19: 0.11 | CB19: 0.003 | CC19: 3 | CE19: 3 | CI19: 6.412 | CJ19: 6.322 | CK19: 37 | CL19: 304 | CM19: 1 | CN19: 1 | CO19: 1 | CP19: 37 | CR19: 25 | CS19: 10 | CU19: 1 | CV19: 3 | CW19: 27.56 | CX19: 0.745 | CY19: 60 | CZ19: 69.8 | DA19: -1.1 | DB19: 0 | DC19: 39 | DD19: 10 | DE19: 7.21 | DF19: 1 | DG19: 0 | DI19: 14 | DL19: 1 | DO19: 31.2 | DP19: 149.74 | DQ19: 74.87 | DR19: 149.74 | DS19: 0 | DT19: 3385 | DU19: 89.09 | DV19: flat | DW19: 27.19 | DX19: 28.81 | DY19: 24.86 | DZ19: -2.32 | EA19: 1614 | EB19: 13.8 | EC19: 0.67 | ED19: 118.86 | EE19: 4019 | EF19: TRUE | EG19: 99.9 | EH19: 17.5 | EI19: 59 | EL19: 1110 | EN19: 30356.3 | EO19: 30356.3 | EP19: 20.6
A20: Dominik Szoboszlai | B20: LIV | C20: MID | D20: MID | E20: 7 | F20: TRUE | G20: TRUE | H20: 25.8 | I20: a | L20: p424876 | M20: 368 | N20: 2 | O20: 1 | P20: 1 | Q20: 3232 | R20: 36 | S20: 36 | T20: 35.911 | U20: 89.8 | V20: 160 | W20: 4.455 | X20: 6 | Y20: 7 | Z20: 7 | AA20: 9 | AB20: 52 | AC20: 21 | AD20: 21 | AE20: 0 | AF20: 780 | AG20: 762 | AH20: -18 | AI20: 160 | AJ20: 0.131 | AK20: 0.151 | AL20: 338 | AM20: 9.412 | AN20: 10 | AO20: 20 | AP20: 0.278 | AQ20: 0.389 | AR20: 0.278 | AS20: 0.947 | AT20: 1 | AU20: 14 | AV20: 5 | AW20: 3.75 | AX20: 13 | AY20: 4.76 | AZ20: 4.724 | BA20: 4.742 | BB20: 3.963 | BC20: 0.133 | BD20: 0.132 | BE20: 0.132 | BF20: 4.2 | BG20: 0.117 | BH20: 0.797 | BI20: 15.34 | BJ20: 3.793 | BK20: 0.106 | BL20: 1.258 | BM20: -0.56 | BN20: 1.8 | BO20: 0.036 | BP20: 71 | BQ20: 23 | BR20: 4 | BS20: 69 | BT20: 1.921 | BW20: 6.83 | BX20: 8.835 | BY20: 7.833 | BZ20: 0.218 | CA20: 12.575 | CB20: 0.35 | CC20: 78 | CD20: 14 | CE20: 78 | CF20: 68 | CG20: 2 | CH20: 104 | CI20: 21.543 | CJ20: 15.062 | CK20: 96 | CL20: 186 | CM20: 56 | CN20: 32 | CO20: 30 | CP20: 58 | CQ20: 8 | CR20: 131 | CS20: 19 | CT20: 0.6 | CU20: 2 | CV20: 5 | CW20: 45.63 | CX20: 1.271 | CY20: 0 | DB20: 0 | DE20: 7.5 | DF20: 8 | DG20: 1 | DH20: 41 | DI20: 30 | DL20: 26 | DM20: 27 | DN20: 2 | DO20: 42.7 | DP20: 184.21 | DQ20: 92.1 | DR20: 184.2 | DS20: 0.01 | DT20: 3344 | DU20: 88 | DV20: flat | DW20: 19.4 | DX20: 18.89 | DY20: 19.18 | DZ20: -0.22 | EA20: 1607 | EB20: 9.15 | EC20: 1 | ED20: 80 | EE20: 3829 | EF20: TRUE | EG20: 99.9 | EH20: 21.4 | EI20: 23 | EJ20: 45.5 | EK20: 46.8 | EL20: 41.4 | EM20: 681.6 | EN20: 412.6 | EO20: 257 | EP20: 20.2
A21: Nico O'Reilly | B21: MCI | C21: DEF | D21: DEF | E21: 6.5 | F21: TRUE | G21: TRUE | H21: 21.4 | I21: a | L21: p472769 | M21: 387 | Q21: 2643 | R21: 34 | S21: 29 | T21: 29.367 | U21: 77.7 | V21: 160 | W21: 5.448 | X21: 5 | Y21: 4 | Z21: 3 | AA21: 14 | AB21: 25 | AC21: 10 | AD21: 11 | AE21: 1 | AF21: 567 | AG21: 549 | AH21: -18 | AI21: 161 | AJ21: 0.062 | AK21: 0.067 | AL21: 172 | AM21: 5.857 | AN21: 1 | AO21: 2 | AP21: 0.034 | AQ21: 0.034 | AR21: 0 | AS21: 0.763 | AT21: 0.824 | AU21: 16 | AV21: 5 | AW21: 4.41 | AX21: 17 | AY21: 6.12 | AZ21: 6.727 | BA21: 6.424 | BB21: 6.727 | BC21: 0.208 | BD21: 0.229 | BE21: 0.219 | BF21: 6.2 | BG21: 0.211 | BH21: 1.039 | BI21: 7.4 | BJ21: 6.358 | BK21: 0.217 | BL21: -1.424 | BM21: 0.08 | BN21: -1.2 | BO21: -0.607 | BP21: 41 | BQ21: 15 | BR21: 7 | BS21: 103 | BT21: 3.507 | BV21: 2 | BW21: 2.67 | BX21: 3.847 | BY21: 3.259 | BZ21: 0.111 | CA21: 9.682 | CB21: 0.33 | CC21: 23 | CD21: 6 | CE21: 23 | CF21: 9 | CG21: 1 | CI21: 21.241 | CJ21: 14.798 | CK21: 105 | CL21: 108 | CM21: 67 | CN21: 36 | CO21: 20 | CP21: 72 | CQ21: 12 | CR21: 161 | CS21: 51 | CT21: 0.4 | CV21: 1 | CW21: 34.97 | CX21: 1.191 | CY21: 0 | DB21: 0 | DE21: 7.17 | DF21: 5 | DG21: 0 | DH21: 45 | DI21: 18 | DL21: 24 | DM21: 34 | DN21: 1 | DO21: 22.2 | DP21: 142.55 | DQ21: 71.97 | DR21: 143.94 | DS21: -1.39 | DT21: 2753 | DU21: 72.45 | DV21: flat | DW21: 26.77 | DX21: 27.34 | DY21: 25.31 | DZ21: -1.47 | EA21: 1632 | EB21: 9.09 | EC21: 2 | ED21: 78.67 | EE21: 3836 | EF21: TRUE | EG21: 99.9 | EH21: 21.2 | EI21: 34 | EJ21: 64.5 | EK21: 25.7 | EL21: 114.9 | EM21: 411.5 | EN21: 811.1 | EO21: 273 | EP21: 16.5
A22: James Garner | B22: EVE | C22: MID | D22: MID | E22: 6 | F22: TRUE | G22: TRUE | H22: 25.4 | I22: i | J22: Groin injury - Expected back 22 Aug | K22: 0 | L22: p232928 | M22: 239 | N22: 3 | O22: 1 | P22: 1 | Q22: 3413 | R22: 38 | S22: 38 | T22: 37.922 | U22: 89.8 | V22: 159 | W22: 4.193 | X22: 2 | Y22: 7 | Z22: 7 | AA22: 11 | AB22: 50 | AC22: 13 | AD22: 12 | AE22: -1 | AF22: 818 | AG22: 788 | AH22: -30 | AI22: 158 | AJ22: 0.082 | AK22: 0.089 | AL22: 458 | AM22: 12.077 | AN22: 20 | AO22: 40 | AP22: 0.526 | AQ22: 0.632 | AR22: 0.526 | AS22: 1 | AT22: 1 | AU22: 10 | AV22: 3 | AW22: 2.89 | AX22: 16 | AY22: 2.1 | AZ22: 2.076 | BA22: 2.088 | BB22: 2.076 | BC22: 0.055 | BD22: 0.055 | BE22: 0.055 | BF22: 1.3 | BG22: 0.034 | BH22: 0.916 | BI22: 6.09 | BJ22: 1.923 | BK22: 0.051 | BL22: -0.088 | BM22: -0.8 | BN22: 0.7 | BO22: 0.024 | BP22: 45 | BQ22: 14 | BS22: 27 | BT22: 0.712 | BW22: 6.18 | BX22: 6.067 | BY22: 6.123 | BZ22: 0.161 | CA22: 8.211 | CB22: 0.217 | CC22: 56 | CD22: 12 | CE22: 56 | CF22: 53 | CG22: 3 | CH22: 110 | CI22: 11.283 | CJ22: 8.333 | CK22: 154 | CL22: 185 | CM22: 119 | CN22: 71 | CO22: 59 | CP22: 85 | CQ22: 10 | CR22: 209 | CS22: 30 | CT22: 0.4 | CV22: 1 | CW22: 56.18 | CX22: 1.481 | CY22: 0 | DB22: 0 | DE22: 7.4 | DF22: 12 | DG22: 0 | DH22: 39 | DI22: 42 | DL22: 18 | DM22: 15 | DO22: 0.4 | DP22: 137.8 | DQ22: 65.66 | DR22: 131.32 | DS22: 6.48 | DT22: 3310 | DU22: 87.1 | DV22: flat | DW22: 77.58 | DX22: 79.36 | DY22: 78.01 | DZ22: 0.43 | EA22: 431 | EB22: 21.43 | EC22: 9.78 | ED22: 120 | EE22: 827 | EF22: TRUE | EG22: 20.4 | EH22: 16.7 | EI22: 60 | EJ22: 75.8 | EK22: 126.4 | EL22: 60.9 | EM22: 1634.7 | EN22: 557.4 | EO22: 415.7 | EP22: 21.5
A23: Enzo Fernández | B23: CHE | C23: MID | D23: MID | E23: 7 | F23: TRUE | G23: TRUE | H23: 25.6 | I23: a | L23: p448047 | M23: 155 | N23: 2 | O23: 2 | P23: 2 | Q23: 3114 | R23: 36 | S23: 35 | T23: 34.6 | U23: 86.5 | V23: 157 | W23: 4.538 | X23: 10 | Y23: 5 | Z23: 4 | AA23: 8 | AB23: 46 | AC23: 19 | AD23: 19 | AE23: 0 | AF23: 700 | AG23: 697 | AH23: -3 | AI23: 157 | AJ23: 0.121 | AK23: 0.138 | AL23: 244 | AM23: 7.052 | AN23: 2 | AO23: 4 | AP23: 0.057 | AQ23: 0.171 | AR23: 0.057 | AS23: 0.921 | AT23: 0.972 | AU23: 19 | AV23: 5 | AW23: 3.76 | AX23: 13 | AY23: 11.26 | AZ23: 11.917 | BA23: 11.589 | BB23: 10.395 | BC23: 0.325 | BD23: 0.344 | BE23: 0.335 | BF23: 12.4 | BG23: 0.358 | BH23: 1.06 | BI23: 23.99 | BJ23: 11.932 | BK23: 0.345 | BL23: -1.589 | BM23: 1.14 | BN23: -2.4 | BO23: -0.657 | BP23: 72 | BQ23: 31 | BR23: 9 | BS23: 102 | BT23: 2.948 | BU23: 2 | BV23: 1 | BW23: 7.26 | BX23: 8.866 | BY23: 8.063 | BZ23: 0.233 | CA23: 19.652 | CB23: 0.568 | CC23: 68 | CD23: 11 | CE23: 68 | CF23: 16 | CG23: 11 | CH23: 55 | CI23: 27.902 | CJ23: 16.16 | CK23: 51 | CL23: 140 | CM23: 53 | CN23: 22 | CO23: 21 | CP23: 28 | CQ23: 2 | CR23: 137 | CS23: 26 | CT23: 0.4 | CW23: 44.89 | CX23: 1.297 | CY23: 0 | DB23: 0 | DE23: 7.3 | DF23: 10 | DG23: 0 | DH23: 36 | DI23: 45 | DL23: 13 | DM23: 41 | DN23: 1 | DO23: 5.6 | DP23: 150.5 | DQ23: 74.85 | DR23: 149.7 | DS23: 0.8 | DT23: 3146 | DU23: 82.8 | DV23: flat | DW23: 36.86 | DX23: 33.88 | DY23: 37.22 | DZ23: 0.36 | EA23: 1415 | EB23: 20.1 | EC23: 1.5 | ED23: 120 | EE23: 2487 | EF23: TRUE | EG23: 98.5 | EH23: 48.2 | EI23: 24 | EJ23: 43.2 | EK23: 30.5 | EL23: 45.8 | EM23: 268.7 | EN23: 386.2 | EO23: 158.5 | EP23: 19.8
A24: Bukayo Saka | B24: ARS | C24: MID | D24: MID | E24: 9.5 | F24: TRUE | G24: TRUE | H24: 25 | I24: a | L24: p223340 | M24: 12 | N24: 1 | O24: 2 | P24: 2 | Q24: 2218 | R24: 31 | S24: 25 | T24: 24.644 | U24: 71.5 | V24: 157 | W24: 6.371 | X24: 7 | Y24: 10 | Z24: 5 | AA24: 12 | AB24: 16 | AC24: 18 | AD24: 16 | AE24: -2 | AF24: 570 | AG24: 565 | AH24: -5 | AI24: 155 | AJ24: 0.115 | AK24: 0.129 | AL24: 184 | AM24: 7.466 | AN24: 5 | AO24: 10 | AP24: 0.2 | AQ24: 0.2 | AR24: 0.2 | AS24: 0.658 | AT24: 0.742 | AU24: 8 | AV24: 5 | AW24: 3.69 | AX24: 12 | AY24: 7.57 | AZ24: 8.701 | BA24: 8.136 | BB24: 7.94 | BC24: 0.307 | BD24: 0.353 | BE24: 0.33 | BF24: 6.1 | BG24: 0.248 | BH24: 0.963 | BI24: 41.33 | BJ24: 7.289 | BK24: 0.296 | BL24: -1.136 | BM24: -1.47 | BN24: 0.9 | BO24: -1.131 | BP24: 71 | BQ24: 27 | BR24: 8 | BS24: 185 | BT24: 7.507 | BU24: 1 | BV24: 1 | BW24: 7.16 | BX24: 8.553 | BY24: 7.856 | BZ24: 0.319 | CA24: 15.992 | CB24: 0.649 | CC24: 62 | CD24: 12 | CE24: 61 | CF24: 40 | CG24: 2 | CH24: 65 | CI24: 19.113 | CJ24: 8.038 | CK24: 28 | CL24: 116 | CM24: 40 | CN24: 21 | CO24: 16 | CP24: 11 | CQ24: 1 | CR24: 167 | CS24: 22 | CT24: 1.1 | CV24: 1 | CW24: 15.57 | CX24: 0.632 | CY24: 0 | DB24: 0 | DE24: 7.52 | DF24: 2 | DG24: 0 | DH24: 33 | DI24: 54 | DJ24: 0 | DL24: 50 | DM24: 32 | DN24: 14 | DO24: 10.6 | DP24: 191.85 | DQ24: 94.81 | DR24: 189.62 | DS24: 2.23 | DT24: 2827 | DU24: 74.4 | DV24: flat | DW24: 6.19 | DX24: 5.05 | DY24: 5.87 | DZ24: -0.33 | EA24: 1334 | EB24: 6.79 | EC24: 0.5 | ED24: 120 | EE24: 2394 | EF24: TRUE | EG24: 99.9 | EH24: 50.8 | EI24: 3 | EJ24: 31.2 | EK24: 12 | EL24: 36.4 | EM24: 272.6 | EN24: 282.3 | EO24: 138.7 | EP24: 14.1
A25: Maxence Lacroix | B25: CHE | C25: DEF | D25: DEF | E25: 6 | F25: TRUE | G25: TRUE | H25: 26.4 | I25: a | L25: p437499 | M25: 200 | Q25: 3085 | R25: 35 | S25: 35 | T25: 34.278 | U25: 88.1 | V25: 154 | W25: 4.493 | X25: 1 | Y25: 2 | Z25: 2 | AA25: 11 | AB25: 47 | AC25: 11 | AD25: 12 | AE25: 1 | AF25: 529 | AG25: 474 | AH25: -55 | AI25: 155 | AJ25: 0.071 | AK25: 0.077 | AL25: 370 | AM25: 10.794 | AN25: 20 | AO25: 40 | AP25: 0.571 | AQ25: 0.571 | AR25: 0.371 | AS25: 0.921 | AT25: 0.971 | AU25: 12 | AV25: 4 | AW25: 3.4 | AX25: 11 | AY25: 2.45 | AZ25: 3.007 | BA25: 2.728 | BB25: 3.007 | BC25: 0.071 | BD25: 0.088 | BE25: 0.08 | BF25: 1.5 | BG25: 0.044 | BH25: 0.803 | BI25: 5.95 | BJ25: 1.967 | BK25: 0.057 | BL25: -1.728 | BM25: -0.95 | BN25: -0.5 | BO25: -0.557 | BP25: 24 | BQ25: 7 | BR25: 2 | BS25: 74 | BT25: 2.159 | BV25: 1 | BW25: 0.83 | BX25: 1.287 | BY25: 1.058 | BZ25: 0.031 | CA25: 3.787 | CB25: 0.11 | CC25: 7 | CD25: 3 | CE25: 7 | CF25: 2 | CI25: 10.744 | CJ25: 9.981 | CK25: 310 | CL25: 96 | CM25: 60 | CN25: 38 | CO25: 45 | CP25: 252 | CQ25: 18 | CR25: 204 | CS25: 119 | CT25: 0 | CU25: 1 | CV25: 2 | CW25: 44.04 | CX25: 1.285 | CY25: 0 | DB25: 0 | DE25: 7.04 | DF25: 4 | DG25: 1 | DH25: 34 | DI25: 19 | DK25: 2 | DL25: 7 | DM25: 6 | DO25: 11.2 | DP25: 104.52 | DQ25: 52.6 | DR25: 105.2 | DS25: -0.68 | DT25: 2189 | DU25: 57.6 | DV25: flat | DW25: 47.76 | DX25: 48.16 | DY25: 45.65 | DZ25: -2.11 | EA25: 1563 | EB25: 14.6 | EC25: 5.09 | ED25: 115.43 | EE25: 3223 | EF25: TRUE | EG25: 99.9 | EH25: 33.8 | EI25: 61 | EJ25: 128.5 | EK25: 41.7 | EL25: 440.7 | EM25: 1130.7 | EN25: 2914.7 | EO25: 814.7 | EP25: 20
A26: Bruno Guimarães | B26: ARS | C26: MID | D26: MID | E26: 7 | F26: TRUE | G26: TRUE | H26: 28.8 | I26: a | L26: p208706 | M26: 452 | Q26: 2456 | R26: 29 | S26: 27 | T26: 27.289 | U26: 84.7 | V26: 154 | W26: 5.643 | X26: 9 | Y26: 7 | Z26: 5 | AA26: 6 | AB26: 37 | AC26: 22 | AD26: 22 | AE26: 0 | AF26: 681 | AG26: 673 | AH26: -8 | AI26: 154 | AJ26: 0.143 | AK26: 0.167 | AL26: 251 | AM26: 9.198 | AN26: 5 | AO26: 10 | AP26: 0.185 | AQ26: 0.481 | AR26: 0.185 | AS26: 0.711 | AT26: 0.931 | AU26: 9 | AV26: 8 | AW26: 4.02 | AX26: 14 | AY26: 5.59 | AZ26: 6.597 | BA26: 6.094 | BB26: 5.075 | BC26: 0.205 | BD26: 0.242 | BE26: 0.223 | BF26: 8.6 | BG26: 0.315 | BH26: 1.107 | BI26: 17.66 | BJ26: 6.187 | BK26: 0.227 | BL26: 2.906 | BM26: 3.01 | BN26: 0.4 | BO26: -1.007 | BP26: 42 | BQ26: 23 | BR26: 4 | BS26: 55 | BT26: 2.015 | BU26: 2 | BV26: 2 | BW26: 4.96 | BX26: 3.869 | BY26: 4.415 | BZ26: 0.162 | CA26: 10.508 | CB26: 0.385 | CC26: 44 | CD26: 7 | CE26: 45 | CF26: 21 | CG26: 8 | CH26: 44 | CI26: 14.098 | CJ26: 9.366 | CK26: 55 | CL26: 134 | CM26: 62 | CN26: 43 | CO26: 15 | CP26: 36 | CQ26: 3 | CR26: 168 | CS26: 13 | CT26: 0.7 | CW26: 31.99 | CX26: 1.172 | CY26: 0 | DB26: 0 | DE26: 7.52 | DF26: 6 | DG26: 0 | DH26: 45 | DI26: 75 | DJ26: 2 | DL26: 18 | DM26: 46 | DN26: 2 | DO26: 10.3 | DP26: 144.73 | DQ26: 72.49 | DR26: 144.98 | DS26: -0.25 | DT26: 2816 | DU26: 74.1 | DV26: flat | DW26: 29.88 | DX26: 27.86 | DY26: 29.67 | DZ26: -0.2 | EA26: 1510 | EB26: 16.13 | EC26: 1.6 | ED26: 117.33 | EE26: 2978 | EF26: TRUE | EG26: 99.1 | EH26: 38.3 | EI26: 25 | EJ26: 58.5 | EK26: 44.7 | EL26: 54.6 | EM26: 403 | EN26: 556.3 | EO26: 233.7 | EP26: 15.9
A27: Matheus Nunes | B27: MCI | C27: DEF | D27: DEF | E27: 6 | F27: TRUE | G27: TRUE | H27: 28 | I27: a | L27: p465351 | M27: 389 | N27: 5 | Q27: 2861 | R27: 34 | S27: 32 | T27: 31.789 | U27: 84.1 | V27: 154 | W27: 4.844 | X27: 1 | Y27: 8 | Z27: 5 | AA27: 12 | AB27: 28 | AC27: 16 | AD27: 16 | AE27: 0 | AF27: 676 | AG27: 653 | AH27: -23 | AI27: 154 | AJ27: 0.104 | AK27: 0.116 | AL27: 195 | AM27: 6.134 | AN27: 4 | AO27: 8 | AP27: 0.125 | AQ27: 0.125 | AR27: 0 | AS27: 0.842 | AT27: 0.882 | AU27: 16 | AV27: 5 | AW27: 3.74 | AX27: 13 | AY27: 0.34 | AZ27: 0.675 | BA27: 0.508 | BB27: 0.675 | BC27: 0.011 | BD27: 0.021 | BE27: 0.016 | BF27: 1 | BG27: 0.031 | BH27: 0.98 | BI27: 4.75 | BJ27: 0.333 | BK27: 0.01 | BL27: 0.492 | BM27: 0.66 | BN27: 0 | BO27: -0.335 | BP27: 7 | BQ27: 2 | BS27: 40 | BT27: 1.258 | BW27: 2.23 | BX27: 3.099 | BY27: 2.665 | BZ27: 0.084 | CA27: 3.172 | CB27: 0.1 | CC27: 28 | CD27: 6 | CE27: 28 | CF27: 16 | CG27: 2 | CH27: 1 | CI27: 22.104 | CJ27: 20.289 | CK27: 138 | CL27: 166 | CM27: 57 | CN27: 40 | CO27: 30 | CP27: 100 | CQ27: 8 | CR27: 157 | CS27: 42 | CT27: 0.3 | CU27: 1 | CV27: 2 | CW27: 34.89 | CX27: 1.098 | CY27: 0 | DB27: 0 | DE27: 7.45 | DF27: 5 | DG27: 0 | DH27: 17 | DI27: 30 | DJ27: 1 | DK27: 1 | DL27: 28 | DM27: 18 | DN27: 4 | DO27: 4.6 | DP27: 138.68 | DQ27: 69.34 | DR27: 138.68 | DS27: 0 | DT27: 2896 | DU27: 76.2 | DV27: flat | DW27: 51.35 | DX27: 51.95 | DY27: 50.23 | DZ27: -1.12 | EA27: 1542 | EB27: 16.42 | EC27: 8 | ED27: 120 | EE27: 2920 | EF27: TRUE | EG27: 99.5 | EH27: 39.8 | EI27: 62 | EJ27: 408.7 | EK27: 71.5 | EL27: 102.2 | EM27: 5634.8 | EN27: 1073.7 | EO27: 901.9 | EP27: 18.6
A28: Nordi Mukiele | B28: SUN | C28: DEF | D28: DEF | E28: 5.5 | F28: TRUE | G28: TRUE | H28: 28.8 | I28: d | J28: Knock - 75% chance of playing | K28: 75 | L28: p200834 | M28: 533 | Q28: 2784 | R28: 32 | S28: 32 | T28: 30.933 | U28: 87 | V28: 151 | W28: 4.881 | X28: 3 | Y28: 5 | Z28: 4 | AA28: 9 | AB28: 40 | AC28: 11 | AD28: 11 | AE28: 0 | AF28: 489 | AG28: 452 | AH28: -37 | AI28: 151 | AJ28: 0.073 | AK28: 0.079 | AL28: 273 | AM28: 8.825 | AN28: 13 | AO28: 26 | AP28: 0.406 | AQ28: 0.406 | AR28: 0.281 | AS28: 0.842 | AT28: 0.969 | AU28: 11 | AV28: 5 | AW28: 4.29 | AX28: 17 | AY28: 1.62 | AZ28: 2.779 | BA28: 2.199 | BB28: 2.779 | BC28: 0.052 | BD28: 0.09 | BE28: 0.071 | BF28: 1.3 | BG28: 0.042 | BH28: 0.967 | BI28: 1.62 | BJ28: 1.566 | BK28: 0.051 | BL28: 0.801 | BM28: -0.32 | BN28: 1.7 | BO28: -1.159 | BP28: 26 | BQ28: 4 | BR28: 3 | BS28: 58 | BT28: 1.875 | BV28: 1 | BW28: 2.65 | BX28: 2.753 | BY28: 2.701 | BZ28: 0.087 | CA28: 4.901 | CB28: 0.158 | CC28: 23 | CD28: 7 | CE28: 24 | CF28: 14 | CG28: 2 | CI28: 9.077 | CJ28: 6.989 | CK28: 204 | CL28: 131 | CM28: 69 | CN28: 46 | CO28: 40 | CP28: 156 | CQ28: 10 | CR28: 183 | CS28: 79 | CT28: 0.1 | CU28: 1 | CV28: 2 | CW28: 44.71 | CX28: 1.445 | CY28: 0 | DB28: 0 | DE28: 7.13 | DF28: 5 | DG28: 0 | DH28: 35 | DI28: 26 | DL28: 13 | DM28: 15 | DN28: 3 | DO28: 4.4 | DP28: 137.29 | DQ28: 68.65 | DR28: 137.3 | DS28: -0.01 | DT28: 3312 | DU28: 87.15 | DV28: flat | DW28: 73.43 | DX28: 70.7 | DY28: 79.32 | DZ28: 5.89 | EA28: 978 | EB28: 19.25 | EC28: 10.67 | ED28: 120 | EE28: 2071 | EF28: TRUE | EG28: 92.4 | EH28: 54 | EI28: 112 | EJ28: 107.1 | EK28: 48 | EL28: 116 | EM28: 1265.8 | EN28: 1030.6 | EO28: 568.1 | EP28: 18.4
A29: Kiernan Dewsbury-Hall | B29: EVE | C29: MID | D29: MID | E29: 6.5 | F29: TRUE | G29: TRUE | H29: 28 | I29: a | L29: p215413 | M29: 236 | O29: 2 | Q29: 2629 | R29: 31 | S29: 30 | T29: 29.211 | U29: 84.8 | V29: 151 | W29: 5.169 | X29: 8 | Y29: 7 | Z29: 4 | AA29: 8 | AB29: 39 | AC29: 18 | AD29: 18 | AE29: 0 | AF29: 598 | AG29: 589 | AH29: -9 | AI29: 151 | AJ29: 0.119 | AK29: 0.135 | AL29: 230 | AM29: 7.874 | AN29: 5 | AO29: 10 | AP29: 0.167 | AQ29: 0.367 | AR29: 0.167 | AS29: 0.789 | AT29: 0.935 | AU29: 16 | AV29: 4 | AW29: 4.28 | AX29: 16 | AY29: 4.35 | AZ29: 4.33 | BA29: 4.34 | BB29: 4.33 | BC29: 0.149 | BD29: 0.148 | BE29: 0.149 | BF29: 4.8 | BG29: 0.164 | BH29: 1.024 | BI29: 6.74 | BJ29: 4.456 | BK29: 0.153 | BL29: 3.66 | BM29: 0.45 | BN29: 3.2 | BO29: 0.02 | BP29: 39 | BQ29: 15 | BR29: 3 | BS29: 84 | BT29: 2.876 | BW29: 5.34 | BX29: 6.575 | BY29: 5.957 | BZ29: 0.204 | CA29: 10.297 | CB29: 0.353 | CC29: 36 | CD29: 10 | CE29: 37 | CF29: 21 | CG29: 1 | CH29: 43 | CI29: 14.278 | CJ29: 8.121 | CK29: 44 | CL29: 134 | CM29: 52 | CN29: 25 | CO29: 12 | CP29: 28 | CQ29: 4 | CR29: 147 | CS29: 21 | CT29: 0.7 | CV29: 1 | CW29: 40.38 | CX29: 1.382 | CY29: 0 | DB29: 0 | DE29: 7.17 | DF29: 6 | DG29: 0 | DH29: 32 | DI29: 48 | DK29: 1 | DL29: 27 | DM29: 49 | DN29: 2 | DO29: 3.7 | DP29: 146.14 | DQ29: 73.2 | DR29: 146.4 | DS29: -0.26 | DT29: 3152 | DU29: 82.95 | DV29: flat | DW29: 51.14 | DX29: 48.49 | DY29: 51.24 | DZ29: 0.11 | EA29: 1311 | EB29: 21.38 | EC29: 3.5 | ED29: 120 | EE29: 2396 | EF29: TRUE | EG29: 93.5 | EH29: 47.4 | EI29: 35 | EJ29: 67.4 | EK29: 31.3 | EL29: 71.1 | EM29: 605.8 | EN29: 441.3 | EO29: 255.3 | EP29: 17.4
A30: Jurriën Timber | B30: ARS | C30: DEF | D30: DEF | E30: 6.5 | F30: TRUE | G30: TRUE | H30: 25.2 | I30: i | J30: Groin injury - Unknown return date | K30: 0 | L30: p445122 | M30: 5 | Q30: 2452 | R30: 30 | S30: 28 | T30: 27.244 | U30: 81.7 | V30: 149 | W30: 5.469 | X30: 3 | Y30: 6 | Z30: 5 | AA30: 13 | AB30: 20 | AC30: 9 | AD30: 10 | AE30: 1 | AF30: 532 | AG30: 514 | AH30: -18 | AI30: 150 | AJ30: 0.06 | AK30: 0.064 | AL30: 148 | AM30: 5.432 | AN30: 3 | AO30: 6 | AP30: 0.107 | AQ30: 0.107 | AR30: 0.036 | AS30: 0.737 | AT30: 0.867 | AU30: 12 | AV30: 3 | AW30: 4.75 | AX30: 24 | AY30: 4.71 | AZ30: 4.031 | BA30: 4.37 | BB30: 4.031 | BC30: 0.173 | BD30: 0.148 | BE30: 0.16 | BF30: 4.2 | BG30: 0.154 | BH30: 0.933 | BI30: 5.94 | BJ30: 4.392 | BK30: 0.161 | BL30: -1.37 | BM30: -0.51 | BN30: -1.2 | BO30: 0.679 | BP30: 25 | BQ30: 7 | BR30: 7 | BS30: 91 | BT30: 3.34 | BV30: 2 | BW30: 1.53 | BX30: 2.589 | BY30: 2.06 | BZ30: 0.076 | CA30: 6.43 | CB30: 0.236 | CC30: 28 | CD30: 4 | CE30: 27 | CF30: 6 | CG30: 3 | CH30: 1 | CI30: 11.439 | CJ30: 8.659 | CK30: 82 | CL30: 97 | CM30: 66 | CN30: 37 | CO30: 24 | CP30: 53 | CQ30: 6 | CR30: 147 | CS30: 40 | CT30: 0.3 | CV30: 1 | CW30: 17.45 | CX30: 0.64 | CY30: 0 | DB30: 0 | DE30: 7.26 | DF30: 5 | DG30: 0 | DH30: 38 | DI30: 29 | DJ30: 1 | DL30: 13 | DM30: 25 | DN30: 0 | DO30: 0.3 | DP30: 154.51 | DQ30: 74.34 | DR30: 148.68 | DS30: 5.83 | DT30: 2878 | DU30: 75.75 | DV30: flat | DW30: 54.07 | DX30: 48.52 | DY30: 63.1 | DZ30: 9.02 | EA30: 1034 | EB30: 23.71 | EC30: 5.6 | ED30: 120 | EE30: 2178 | EF30: TRUE | EG30: 95.2 | EH30: 53.1 | EI30: 36 | EJ30: 98.1 | EK30: 26.9 | EL30: 90.8 | EM30: 561 | EN30: 1190.5 | EO30: 381.3 | EP30: 16.5
A31: Bryan Mbeumo | B31: MUN | C31: MID | D31: MID | E31: 8 | F31: TRUE | G31: TRUE | H31: 27 | I31: a | L31: p446008 | M31: 427 | N31: 2 | O31: 2 | P31: 2 | Q31: 2611 | R31: 33 | S31: 31 | T31: 29.011 | U31: 79.1 | V31: 148 | W31: 5.101 | X31: 11 | Y31: 3 | Z31: 3 | AA31: 8 | AB31: 37 | AC31: 16 | AD31: 17 | AE31: 1 | AF31: 528 | AG31: 525 | AH31: -3 | AI31: 149 | AJ31: 0.108 | AK31: 0.121 | AL31: 139 | AM31: 4.791 | AN31: 0 | AO31: 0 | AP31: 0 | AQ31: 0.032 | AR31: 0 | AS31: 0.816 | AT31: 0.939 | AU31: 17 | AV31: 3 | AW31: 3.7 | AX31: 15 | AY31: 11.98 | AZ31: 13.309 | BA31: 12.645 | BB31: 13.309 | BC31: 0.413 | BD31: 0.459 | BE31: 0.436 | BF31: 9.9 | BG31: 0.341 | BH31: 1.029 | BI31: 43.68 | BJ31: 12.332 | BK31: 0.425 | BL31: -1.645 | BM31: -2.08 | BN31: 1.1 | BO31: -1.329 | BP31: 73 | BQ31: 32 | BR31: 13 | BS31: 150 | BT31: 5.17 | BV31: 1 | BW31: 4.99 | BX31: 5.091 | BY31: 5.041 | BZ31: 0.174 | CA31: 17.685 | CB31: 0.61 | CC31: 45 | CD31: 6 | CE31: 47 | CF31: 35 | CG31: 6 | CH31: 49 | CI31: 22.316 | CJ31: 6.068 | CK31: 23 | CL31: 91 | CM31: 25 | CN31: 11 | CO31: 8 | CP31: 14 | CQ31: 1 | CR31: 86 | CS31: 15 | CT31: 0.7 | CV31: 1 | CW31: 35.87 | CX31: 1.236 | CY31: 0 | DB31: 0 | DE31: 7.19 | DF31: 4 | DG31: 0 | DH31: 23 | DI31: 28 | DJ31: 1 | DL31: 18 | DM31: 29 | DN31: 7 | DO31: 26.7 | DP31: 166.11 | DQ31: 83.42 | DR31: 166.84 | DS31: -0.73 | DT31: 2822 | DU31: 74.25 | DV31: flat | DW31: 12.94 | DX31: 11.86 | DY31: 12.14 | DZ31: -0.81 | EA31: 1530 | EB31: 8.41 | EC31: 1.33 | ED31: 108 | EE31: 3137 | EF31: TRUE | EG31: 99.9 | EH31: 35.6 | EI31: 11 | EJ31: 35.8 | EK31: 17.4 | EL31: 55.6 | EM31: 206.5 | EN31: 518 | EO31: 147.6 | EP31: 17.6
A32: Jan Paul van Hecke | B32: TOT | C32: DEF | D32: DEF | E32: 5 | F32: TRUE | G32: TRUE | H32: 26.2 | I32: a | L32: p469142 | M32: 112 | Q32: 3210 | R32: 36 | S32: 36 | T32: 35.667 | U32: 89.2 | V32: 148 | W32: 4.15 | X32: 3 | Y32: 3 | Z32: 3 | AA32: 10 | AB32: 44 | AC32: 8 | AD32: 7 | AE32: -1 | AF32: 575 | AG32: 529 | AH32: -46 | AI32: 147 | AJ32: 0.054 | AK32: 0.057 | AL32: 317 | AM32: 8.888 | AN32: 13 | AO32: 26 | AP32: 0.361 | AQ32: 0.361 | AR32: 0.194 | AS32: 0.947 | AT32: 1 | AU32: 14 | AV32: 2 | AW32: 3 | AX32: 12 | AY32: 3.31 | AZ32: 3.359 | BA32: 3.334 | BB32: 3.359 | BC32: 0.093 | BD32: 0.094 | BE32: 0.093 | BF32: 3.8 | BG32: 0.107 | BH32: 0.973 | BI32: 6.6 | BJ32: 3.219 | BK32: 0.09 | BL32: -0.334 | BM32: 0.49 | BN32: -0.8 | BO32: -0.049 | BP32: 23 | BQ32: 10 | BR32: 3 | BS32: 50 | BT32: 1.402 | BV32: 1 | BW32: 1.57 | BX32: 1.026 | BY32: 1.298 | BZ32: 0.036 | CA32: 4.632 | CB32: 0.13 | CC32: 12 | CD32: 2 | CE32: 13 | CF32: 10 | CI32: 14.122 | CJ32: 13.214 | CK32: 264 | CL32: 113 | CM32: 53 | CN32: 30 | CO32: 47 | CP32: 189 | CQ32: 28 | CR32: 209 | CS32: 114 | CT32: 0.1 | CU32: 4 | CW32: 46.27 | CX32: 1.297 | CY32: 0 | DB32: 0 | DE32: 7.1 | DF32: 9 | DG32: 0 | DH32: 27 | DI32: 43 | DK32: 1 | DL32: 3 | DM32: 6 | DN32: 4 | DO32: 8.6 | DP32: 142.34 | DQ32: 71.17 | DR32: 142.34 | DS32: 0 | DT32: 3181 | DU32: 83.7 | DV32: flat | DW32: 77.47 | DX32: 83.11 | DY32: 73 | DZ32: -4.47 | EA32: 1465 | EB32: 21.4 | EC32: 7 | ED32: 120 | EE32: 3191 | EF32: TRUE | EG32: 87.2 | EH32: 24.9 | EI32: 223 | EJ32: 139.6 | EK32: 64.2 | EL32: 246.9 | EM32: 962.7 | EN32: 2473.4 | EO32: 693 | EP32: 21.7
A33: Enzo Le Fée | B33: SUN | C33: MID | D33: MID | E33: 6 | F33: TRUE | G33: TRUE | H33: 26.5 | I33: a | L33: p484420 | M33: 542 | N33: 2 | O33: 1 | P33: 2 | Q33: 2930 | R33: 36 | S33: 33 | T33: 32.556 | U33: 81.4 | V33: 147 | W33: 4.515 | X33: 5 | Y33: 6 | Z33: 6 | AA33: 10 | AB33: 43 | AC33: 16 | AD33: 15 | AE33: -1 | AF33: 621 | AG33: 602 | AH33: -19 | AI33: 146 | AJ33: 0.109 | AK33: 0.122 | AL33: 319 | AM33: 9.799 | AN33: 8 | AO33: 16 | AP33: 0.242 | AQ33: 0.424 | AR33: 0.242 | AS33: 0.868 | AT33: 0.917 | AU33: 18 | AV33: 4 | AW33: 3.43 | AX33: 13 | AY33: 5.22 | AZ33: 5.269 | BA33: 5.244 | BB33: 2.224 | BC33: 0.16 | BD33: 0.162 | BE33: 0.161 | BF33: 4.9 | BG33: 0.151 | BH33: 0.976 | BI33: 5.22 | BJ33: 5.094 | BK33: 0.156 | BL33: -0.244 | BM33: -0.32 | BN33: 0.1 | BO33: -0.049 | BP33: 36 | BQ33: 12 | BR33: 1 | BS33: 62 | BT33: 1.904 | BU33: 3 | BW33: 5.95 | BX33: 7.546 | BY33: 6.748 | BZ33: 0.207 | CA33: 11.993 | CB33: 0.368 | CC33: 53 | CD33: 13 | CE33: 53 | CF33: 25 | CG33: 9 | CH33: 50 | CI33: 13.18 | CJ33: 7.139 | CK33: 77 | CL33: 153 | CM33: 89 | CN33: 57 | CO33: 29 | CP33: 36 | CQ33: 12 | CR33: 157 | CS33: 18 | CT33: 0.7 | CU33: 1 | CV33: 3 | CW33: 46.5 | CX33: 1.428 | CY33: 0 | DB33: 0 | DE33: 7.14 | DF33: 5 | DG33: 0 | DH33: 31 | DI33: 37 | DL33: 13 | DM33: 31 | DN33: 4 | DO33: 12.8 | DP33: 153.32 | DQ33: 76.66 | DR33: 153.32 | DS33: 0 | DT33: 3324 | DU33: 87.48 | DV33: flat | DW33: 66.58 | DX33: 67.61 | DY33: 65.43 | DZ33: -1.14 | EA33: 1165 | EB33: 21.82 | EC33: 10 | ED33: 120 | EE33: 2833 | EF33: TRUE | EG33: 66.4 | EH33: 12.5 | EI33: 63 | EJ33: 81.4 | EK33: 47.3 | EL33: 55.3 | EM33: 558.7 | EN33: 434.2 | EO33: 244.3 | EP33: 19.9
A34: Ryan Gravenberch | B34: LIV | C34: MID | D34: MID | E34: 6 | F34: TRUE | G34: TRUE | H34: 24.3 | I34: a | L34: p441266 | M34: 371 | Q34: 2991 | R34: 36 | S34: 34 | T34: 33.233 | U34: 83.1 | V34: 144 | W34: 4.333 | X34: 5 | Y34: 5 | Z34: 3 | AA34: 9 | AB34: 42 | AC34: 17 | AD34: 17 | AE34: 0 | AF34: 671 | AG34: 651 | AH34: -20 | AI34: 144 | AJ34: 0.118 | AK34: 0.134 | AL34: 298 | AM34: 8.967 | AN34: 7 | AO34: 14 | AP34: 0.206 | AQ34: 0.382 | AR34: 0.206 | AS34: 0.895 | AT34: 0.917 | AU34: 17 | AV34: 4 | AW34: 3.38 | AX34: 15 | AY34: 1.89 | AZ34: 1.532 | BA34: 1.711 | BB34: 1.532 | BC34: 0.057 | BD34: 0.046 | BE34: 0.051 | BF34: 3.1 | BG34: 0.093 | BH34: 0.985 | BI34: 5.1 | BJ34: 1.861 | BK34: 0.056 | BL34: 3.289 | BM34: 1.21 | BN34: 1.9 | BO34: 0.358 | BP34: 38 | BQ34: 13 | BS34: 31 | BT34: 0.933 | BW34: 2.26 | BX34: 2.369 | BY34: 2.314 | BZ34: 0.07 | CA34: 4.025 | CB34: 0.121 | CC34: 29 | CD34: 4 | CE34: 29 | CF34: 0 | CG34: 3 | CI34: 13.042 | CJ34: 10.719 | CK34: 112 | CL34: 127 | CM34: 59 | CN34: 36 | CO34: 48 | CP34: 53 | CQ34: 12 | CR34: 160 | CS34: 27 | CT34: 0.3 | CV34: 4 | CW34: 38.41 | CX34: 1.156 | CY34: 0 | DB34: 0 | DE34: 7.25 | DF34: 5 | DG34: 0 | DH34: 38 | DI34: 42 | DL34: 32 | DM34: 26 | DO34: 2 | DP34: 121.71 | DQ34: 61.04 | DR34: 122.08 | DS34: -0.37 | DT34: 2964 | DU34: 78 | DV34: flat | DW34: 69.01 | DX34: 73.68 | DY34: 65.97 | DZ34: -3.05 | EA34: 956 | EB34: 22.65 | EC34: 2.67 | ED34: 120 | EE34: 1921 | EF34: TRUE | EG34: 43.8 | EH34: 10 | EI34: 64 | EJ34: 78.7 | EK34: 96.5 | EL34: 103.1 | EM34: 1748.3 | EN34: 1292.3 | EO34: 743.1 | EP34: 20.8
A35: Matheus Cunha | B35: MUN | C35: MID | D35: MID | E35: 8 | F35: TRUE | G35: TRUE | H35: 27.2 | I35: a | L35: p430871 | M35: 428 | Q35: 2493 | R35: 33 | S35: 29 | T35: 27.7 | U35: 75.5 | V35: 143 | W35: 5.162 | X35: 10 | Y35: 4 | Z35: 2 | AA35: 8 | AB35: 35 | AC35: 14 | AD35: 15 | AE35: 1 | AF35: 591 | AG35: 584 | AH35: -7 | AI35: 144 | AJ35: 0.098 | AK35: 0.109 | AL35: 211 | AM35: 7.617 | AN35: 1 | AO35: 2 | AP35: 0.034 | AQ35: 0.138 | AR35: 0.034 | AS35: 0.763 | AT35: 0.848 | AU35: 14 | AV35: 0 | AW35: 3.1 | AX35: 9 | AY35: 6.9 | AZ35: 7.076 | BA35: 6.988 | BB35: 7.076 | BC35: 0.249 | BD35: 0.255 | BE35: 0.252 | BF35: 7.2 | BG35: 0.26 | BH35: 1.053 | BI35: 26.84 | BJ35: 7.268 | BK35: 0.262 | BL35: 3.012 | BM35: 0.3 | BN35: 2.8 | BO35: -0.176 | BP35: 90 | BQ35: 35 | BR35: 4 | BS35: 137 | BT35: 4.946 | BW35: 3.36 | BX35: 3.698 | BY35: 3.529 | BZ35: 0.127 | CA35: 10.517 | CB35: 0.38 | CC35: 33 | CD35: 4 | CE35: 34 | CF35: 11 | CG35: 5 | CH35: 5 | CI35: 17.601 | CJ35: 10.044 | CK35: 46 | CL35: 126 | CM35: 39 | CN35: 23 | CO35: 21 | CP35: 22 | CQ35: 3 | CR35: 164 | CS35: 28 | CT35: 0.7 | CW35: 35.75 | CX35: 1.291 | CY35: 0 | DB35: 0 | DE35: 7.29 | DF35: 4 | DG35: 0 | DH35: 27 | DI35: 54 | DJ35: 2 | DL35: 44 | DM35: 53 | DN35: 2 | DO35: 12.2 | DP35: 153.17 | DQ35: 76.44 | DR35: 152.88 | DS35: 0.29 | DT35: 2616 | DU35: 68.85 | DV35: flat | DW35: 16.49 | DX35: 14.95 | DY35: 16.57 | DZ35: 0.08 | EA35: 1450 | EB35: 9.77 | EC35: 1.71 | ED35: 118.67 | EE35: 2768 | EF35: TRUE | EG35: 99.9 | EH35: 43.2 | EI35: 12 | EJ35: 27.7 | EK35: 18.2 | EL35: 73.3 | EM35: 356.8 | EN35: 706.4 | EO35: 237 | EP35: 17.4
A36: Caoimhín Kelleher | B36: BRE | C36: GKP | D36: GKP | E36: 5 | F36: TRUE | G36: TRUE | H36: 27.7 | I36: a | L36: p200720 | M36: 82 | Q36: 3330 | R36: 37 | S36: 37 | T36: 37 | U36: 90 | V36: 143 | W36: 3.865 | X36: 0 | Y36: 0 | AA36: 10 | AB36: 49 | AC36: 11 | AD36: 14 | AE36: 3 | AF36: 570 | AG36: 562 | AH36: -8 | AI36: 146 | AJ36: 0.077 | AK36: 0.083 | AL36: 0 | AM36: 0 | AN36: 0 | AO36: 0 | AP36: 0 | AQ36: 0 | AR36: 0 | AS36: 0.974 | AT36: 1 | AU36: 21 | AV36: 3 | AW36: 3.36 | AX36: 13 | AY36: 0 | AZ36: 0 | BA36: 0 | BB36: 0 | BC36: 0 | BD36: 0 | BE36: 0 | BH36: 1 | BI36: 0 | BJ36: 0 | BK36: 0 | BL36: 0 | BO36: 0 | BW36: 0.22 | BX36: 0.106 | BY36: 0.163 | BZ36: 0.004 | CA36: 0.163 | CB36: 0.004 | CC36: 2 | CE36: 2 | CG36: 1 | CI36: 5.348 | CJ36: 5.242 | CK36: 48 | CL36: 301 | CM36: 1 | CO36: 1 | CP36: 47 | CR36: 16 | CS36: 7 | CU36: 2 | CV36: 1 | CW36: 53.48 | CX36: 1.445 | CY36: 109 | CZ36: 69.2 | DA36: -0.1 | DB36: 3 | DC36: 27 | DD36: 31 | DE36: 6.93 | DF36: 1 | DG36: 0 | DH36: 3 | DI36: 6 | DK36: 3 | DL36: 3 | DO36: 5.7 | DP36: 127.72 | DQ36: 63.86 | DR36: 127.72 | DS36: 0 | DT36: 3385 | DU36: 89.09 | DV36: flat | DW36: 80.19 | DX36: 84.13 | DY36: 77.19 | DZ36: -2.99 | EA36: 1467 | EB36: 24.4 | EC36: 2.67 | ED36: 120 | EE36: 2818 | EF36: TRUE | EG36: 99.2 | EH36: 41.7 | EI36: 224 | EL36: 1665 | EN36: 20404.3 | EO36: 20404.3 | EP36: 23.3
